<mujoco model="Robot_V3">
    
    <include file="wall.xml"/>
    <include file="groundplane.xml"/>
    <include file="route_ladder_V1.xml"/>

    <option gravity="0 0 -9.81"/>
    <statistic center="0 0 0.2" extent="0.6"/>
    <compiler angle="radian" autolimits="true"/>

    <visual>
        <headlight diffuse="0.6 0.6 0.6" ambient="0.3 0.3 0.3" specular="0 0 0"/>
        <rgba haze="0.15 0.25 0.35 1"/>
        <global azimuth="160" elevation="-20"/>
    </visual>

    <default>
        <position kp="21.1" ctrlrange="-1.5708 1.5708" forcerange="-5 5"/>
        <joint damping="1.084" armature="0.045" frictionloss="0.03"/>
        <geom solref="0.004 1" conaffinity="0" contype="0" />
        <default class="collision_geom">
            <geom type="box" contype="1" conaffinity="1" solimp="0.99 0.99 0.01" solref="0.01 1" rgba="1 0 0 0.3"/>
        </default>
    </default>

    <asset>
        <mesh name="servo_shoulder_roll_r" file="meshes/servo_shoulder_roll_r.stl" scale="0.001 0.001 0.001" />
        <mesh name="servo_shoulder_roll_l" file="meshes/servo_shoulder_roll_l.stl" scale="0.001 0.001 0.001" />
        <mesh name="servo_hip_roll_l" file="meshes/servo_hip_roll_l.stl" scale="0.001 0.001 0.001" />
        <mesh name="servo_hip_roll_r" file="meshes/servo_hip_roll_r.stl" scale="0.001 0.001 0.001" />
        <mesh name="servo_hip_pitch_r" file="meshes/servo_hip_pitch_r.stl" scale="0.001 0.001 0.001" />
        <mesh name="servo_hip_pitch_l" file="meshes/servo_hip_pitch_l.stl" scale="0.001 0.001 0.001" />
        <mesh name="servo_knee_pitch_r" file="meshes/servo_knee_pitch_r.stl" scale="0.001 0.001 0.001" />
        <mesh name="servo_knee_pitch_l" file="meshes/servo_knee_pitch_l.stl" scale="0.001 0.001 0.001" />
        <mesh name="servo_ankle_pitch_r" file="meshes/servo_ankle_pitch_r.stl" scale="0.001 0.001 0.001" />
        <mesh name="servo_ankle_pitch_l" file="meshes/servo_ankle_pitch_l.stl" scale="0.001 0.001 0.001" />
        <mesh name="servo_shoulder_pitch_r" file="meshes/servo_shoulder_pitch_r.stl" scale="0.001 0.001 0.001" />
        <mesh name="servo_elbow_pitch_r" file="meshes/servo_elbow_pitch_r.stl" scale="0.001 0.001 0.001" />
        <mesh name="servo_wrist_pitch_r" file="meshes/servo_wrist_pitch_r.stl" scale="0.001 0.001 0.001" />
        <mesh name="servo_shoulder_pitch_l" file="meshes/servo_shoulder_pitch_l.stl" scale="0.001 0.001 0.001" />
        <mesh name="servo_elbow_pitch_l" file="meshes/servo_elbow_pitch_l.stl" scale="0.001 0.001 0.001" />
        <mesh name="servo_wrist_pitch_l" file="meshes/servo_wrist_pitch_l.stl" scale="0.001 0.001 0.001" />
        <mesh name="hand_r" file="meshes/hand_r.stl" scale="0.001 0.001 0.001" />
        <mesh name="hand_l" file="meshes/hand_l.stl" scale="0.001 0.001 0.001" />
        <mesh name="shoulder_joint_l" file="meshes/shoulder_joint_l.stl" scale="0.001 0.001 0.001" />
        <mesh name="elbow_joint_l" file="meshes/elbow_joint_l.stl" scale="0.001 0.001 0.001" />
        <mesh name="wrist_joint_l" file="meshes/wrist_joint_l.stl" scale="0.001 0.001 0.001" />
        <mesh name="Chest" file="meshes/Chest.stl" scale="0.001 0.001 0.001" />
        <mesh name="shoulder_joint_r" file="meshes/shoulder_joint_r.stl" scale="0.001 0.001 0.001" />
        <mesh name="elbow_joint_r" file="meshes/elbow_joint_r.stl" scale="0.001 0.001 0.001" />
        <mesh name="hip_joint_l" file="meshes/hip_joint_l.stl" scale="0.001 0.001 0.001" />
        <mesh name="wrist_joint_r" file="meshes/wrist_joint_r.stl" scale="0.001 0.001 0.001" />
        <mesh name="knee_joint_l" file="meshes/knee_joint_l.stl" scale="0.001 0.001 0.001" />
        <mesh name="ankle_joint_l" file="meshes/ankle_joint_l.stl" scale="0.001 0.001 0.001" />
        <mesh name="hip_joint_r" file="meshes/hip_joint_r.stl" scale="0.001 0.001 0.001" />
        <mesh name="knee_joint_r" file="meshes/knee_joint_r.stl" scale="0.001 0.001 0.001" />
        <mesh name="ankle_joint_r" file="meshes/ankle_joint_r.stl" scale="0.001 0.001 0.001" />
        <mesh name="foot_r" file="meshes/foot_r.stl" scale="0.001 0.001 0.001" />
        <mesh name="foot_l" file="meshes/foot_l.stl" scale="0.001 0.001 0.001" />
    </asset>
    <worldbody>
        <light directional="true" pos="-0.5 0.5 3" dir="0 0 -1" />

        <body name="chest" pos="0 -0.11 0.18" euler="1.5708 0 0">
            <freejoint/>
            <geom name="Chest_geom" type="mesh" mesh="Chest" pos="0 0 0" euler="0 0 0" />
            <inertial mass="0.7778298243226758" pos="-1.1116181606743858e-15 0.3029679253934266 -0.06434347713139629" fullinertia="0.0009215678074957225 0.0013132174134944975 0.002029370809638653 -3.2314396577744144e-17 9.060671285838158e-18 5.004118512455874e-05" />
            <body name="servo_shoulder_roll_r" pos="-0.06710384800005387 0.32224999417966727 -0.00645434448437209" euler="-3.141592653589793 -1.031119634120601e-14 -1.5707963267948968">
                <geom name="servo_shoulder_roll_r_geom" type="mesh" mesh="servo_shoulder_roll_r" pos="0 0 0" euler="0 0 0" />
                <inertial mass="0.25164687718092266" pos="0.01629552810654563 0.03288647170679024 0.047544912714183846" fullinertia="4.1434323908684105e-05 4.382264111654103e-05 6.93651292815669e-05 1.9005141956634606e-06 -1.019704963049354e-10 -1.6884099916441515e-09" />
                <body name="shoulder_joint_r" pos="0.01600000678890815 0.00870384800005427 0.03754565551562749" euler="8.326672684675602e-17 -1.5707963267948966 0">
                    <joint name="servo_shoulder_roll_r_Revolute_shoulder_roll_r" type="hinge" axis="-3.88578058618812e-16 1.0000000000000004 5.118468290728131e-15" pos="0.010000050104568715 -1.4283053012017503e-07 -0.010000407884751771" />
                    <geom name="shoulder_joint_r_geom" type="mesh" mesh="shoulder_joint_r" pos="0 0 0" euler="0 0 0" />
                    <inertial mass="0.04536367978101092" pos="0.01567916915088002 -0.013944636154283091 -0.0015204553499204784" fullinertia="2.3284052485714027e-05 1.7057494663979933e-05 7.860019450883476e-06 9.022824967103496e-07 -6.427073886898537e-07 9.57685804765672e-07" />
                    <body name="servo_shoulder_pitch_r" pos="0.04445384800005429 -0.06754565551562745 0.016000006788908224" euler="-1.5707963267948968 -6.106226635439103e-16 1.5707963267948961">
                        <geom name="servo_shoulder_pitch_r_geom" type="mesh" mesh="servo_shoulder_pitch_r" pos="0 0 0" euler="0 0 0" />
                        <inertial mass="0.2574774645033229" pos="0.01661236370431344 0.03333463847036319 0.04754288849972701" fullinertia="4.435486308624919e-05 4.572278841337451e-05 7.311602559769578e-05 3.613069512863561e-07 7.0274044862877705e-09 8.375458182036796e-09" />
                        <body name="elbow_joint_r" pos="-0.01449999321109182 0.008703848000054321 0.06154565551562744" euler="3.141592653589793 -2.1632341619893754e-16 -1.5707963267948963">
                            <joint name="servo_shoulder_pitch_r_Revolute_shoulder_pitch_r" type="hinge" axis="1.0 -7.487654456271741e-18 3.885780586188053e-16" pos="-5.010456858259505e-08 0.04050040788475191 0.014000142830530136" />
                            <geom name="elbow_joint_r_geom" type="mesh" mesh="elbow_joint_r" pos="0 0 0" euler="0 0 0" />
                            <inertial mass="0.16360616576335604" pos="0.022760321024193356 0.035866581950933014 0.051311528655864296" fullinertia="0.00011514146448919627 0.0001458301143714972 9.679461265510434e-05 -3.3053664850960324e-06 7.146298961093728e-06 1.2645936324308126e-05" />
                            <body name="servo_elbow_pitch_r" pos="-0.008703848000056197 0.014499993211092174 0.1285456555156282" euler="3.1415926535897847 6.390648064044369e-15 -1.5707963267948968">
                                <geom name="servo_elbow_pitch_r_geom" type="mesh" mesh="servo_elbow_pitch_r" pos="0 0 0" euler="0 0 0" />
                                <inertial mass="0.2574774645033229" pos="0.01661236370431337 0.03333463847036315 0.047542888499726994" fullinertia="4.4354863086253606e-05 4.572278841340221e-05 7.311602559773045e-05 3.6130695128637416e-07 7.0274044917526815e-09 8.37545818359499e-09" />
                                <body name="wrist_joint_r" pos="-0.014499993211092034 0.008703848000054313 0.061545655515627455" euler="-3.141592653589793 3.3878809611363526e-16 -1.5707963267948963">
                                    <joint name="servo_elbow_pitch_r_Revolute_elbow_pitch_r" type="hinge" axis="1.0 2.7006810170006784e-16 -5.918803278578637e-15" pos="-5.010456702355047e-08 0.040500407884752516 0.014000142830529647" />
                                    <geom name="wrist_joint_r_geom" type="mesh" mesh="wrist_joint_r" pos="0 0 0" euler="0 0 0" />
                                    <inertial mass="0.16360616576335604" pos="0.022760321024193397 0.03586658195093304 0.05131152865586432" fullinertia="0.00011514146448919635 0.00014583011437149785 9.679461265510447e-05 -3.305366485095939e-06 7.1462989610940355e-06 1.2645936324306874e-05" />
                                    <body name="servo_wrist_pitch_r" pos="-0.00870384800005442 0.01449999321109285 0.12854565551562794" euler="-3.141592653589793 -9.575673587391948e-15 -1.5707963267948972">
                                        <geom name="servo_wrist_pitch_r_geom" type="mesh" mesh="servo_wrist_pitch_r" pos="0 0 0" euler="0 0 0" />
                                        <inertial mass="0.2574774645033229" pos="0.01661236370431341 0.0333346384703632 0.04754288849972691" fullinertia="4.435486308624465e-05 4.572278841337451e-05 7.311602559769562e-05 3.6130695128635225e-07 7.027404484854914e-09 8.375458182149205e-09" />
                                        <body name="hand_r" pos="0.012000006788907882 0.03345384800005429 0.07154565551562737" euler="2.4980018054065613e-16 -5.417030312083731e-16 -1.5707963267948963">
                                            <joint name="servo_wrist_pitch_r_Revolute_wrist_pitch_r" type="hinge" axis="1.0000000000000004 -6.112916081690817e-16 3.90667048935397e-15" pos="0.02475005010456617 0.014000407884751534 -0.024000142830529144" />
                                            <geom name="hand_r_geom" type="mesh" mesh="hand_r" pos="0 0 0" euler="0 0 0" />
                                            <geom name="hand_r_collision1" class="collision_geom" pos="0.027 0.047 -0.024" size="0.0015 0.04 0.01" />
                                            <geom name="hand_r_collision2" class="collision_geom" pos="0.036 0.0885 -0.024" size="0.0075 0.0015 0.01" />
                                            <geom name="hand_r_collision3" class="collision_geom" pos="0.045 0.085 -0.024" size="0.0015 0.005 0.01" />
                                            <inertial mass="0.017731524807570984" pos="0.00792737188011213 0.05055428177592219 -0.02400000000001018" fullinertia="1.1536574784612629e-05 1.2648677821680248e-05 2.3032321428704507e-05 -4.718790043704861e-06 -7.128239351091303e-18 -6.700273341029526e-18" />
                                        </body>
                                    </body>
                                </body>
                            </body>
                        </body>
                    </body>
                </body>
            </body>
            <body name="servo_shoulder_roll_l" pos="0.06710384800005406 0.32224999417966727 -0.10154565551562776" euler="6.123233995736755e-17 7.4107386893728e-15 1.5707963267948966">
                <geom name="servo_shoulder_roll_l_geom" type="mesh" mesh="servo_shoulder_roll_l" pos="0 0 0" euler="0 0 0" />
                <inertial mass="0.25164687718092266" pos="0.016295528106545623 0.032886471706790266 0.04754491271418395" fullinertia="4.1434323908683766e-05 4.3822641116547954e-05 6.93651292815705e-05 1.9005141956632746e-06 -1.0197049282314026e-10 -1.688409991050593e-09" />
                <body name="shoulder_joint_l" pos="0.016000006788907867 0.008703848000053967 0.05754565551562741" euler="3.141592653589766 -1.5707963267948963 0">
                    <joint name="servo_shoulder_roll_l_Revolute_shoulder_roll_l" type="hinge" axis="-2.6104118866501716e-14 1.0000000000000027 4.632745717452496e-15" pos="0.010000050104569442 -1.4283053038593373e-07 -0.010000407884751506" />
                    <geom name="shoulder_joint_l_geom" type="mesh" mesh="shoulder_joint_l" pos="0 0 0" euler="0 0 0" />
                    <inertial mass="0.04536367978101096" pos="0.015679169150879926 0.013944636154283232 -0.001520455349920564" fullinertia="2.328405248571482e-05 1.7057494663981708e-05 7.860019450883574e-06 -9.022824967103273e-07 -6.427073886902723e-07 -9.576858047654943e-07" />
                    <body name="servo_shoulder_pitch_l" pos="0.044453848000054315 -0.027545655515627418 0.01600000678890794" euler="-1.5707963267948966 2.914335439668928e-16 1.5707963267948966">
                        <geom name="servo_shoulder_pitch_l_geom" type="mesh" mesh="servo_shoulder_pitch_l" pos="0 0 0" euler="0 0 0" />
                        <inertial mass="0.2574774645033229" pos="0.01661236370431341 0.03333463847036318 0.047542888499727244" fullinertia="4.4354863086247046e-05 4.572278841338145e-05 7.311602559771001e-05 3.6130695128290297e-07 7.0274044871896645e-09 8.375458181875714e-09" />
                        <body name="elbow_joint_l" pos="-0.014499993211092068 0.008703848000054304 0.03354565551562747" euler="-1.2490009027035585e-16 -1.74690052775471e-16 -1.5707963267948966">
                            <joint name="servo_shoulder_pitch_l_Revolute_shoulder_pitch_l" type="hinge" axis="0.9999999999999993 7.487654456280702e-18 2.6104118866501666e-14" pos="5.010456886395696e-08 0.04050040788475139 0.013999857169470175" />
                            <geom name="elbow_joint_l_geom" type="mesh" mesh="elbow_joint_l" pos="0 0 0" euler="0 0 0" />
                            <inertial mass="0.16360616576335538" pos="-0.022760321024193408 0.03586658195093304 0.05131152865552524" fullinertia="0.00011514146451670573 0.00014583011440746257 9.679461264664905e-05 3.3053664850957647e-06 -7.146298961246289e-06 1.264593632456282e-05" />
                            <body name="servo_elbow_pitch_l" pos="0.008703848000052732 0.01449999321109285 0.03345434448437297" euler="-3.5613533087633844e-16 -2.6062485503078358e-14 1.5707963267948966">
                                <geom name="servo_elbow_pitch_l_geom" type="mesh" mesh="servo_elbow_pitch_l" pos="0 0 0" euler="0 0 0" />
                                <inertial mass="0.2574774645033229" pos="0.016612363704313304 0.03333463847036304 0.047542888499726974" fullinertia="4.435486308624562e-05 4.572278841338817e-05 7.311602559771652e-05 3.613069512863765e-07 7.027404486315356e-09 8.375458182458407e-09" />
                                <body name="wrist_joint_l" pos="-0.014499993211091855 0.00870384800005433 0.033545655515627305" euler="-1.3877787807814496e-16 -2.2034386889519166e-17 -1.5707963267948966">
                                    <joint name="servo_elbow_pitch_l_Revolute_elbow_pitch_l" type="hinge" axis="1.0000000000000004 7.487654456271864e-18 -9.714451465481853e-17" pos="5.0104569952415925e-08 0.04050040788475 0.013999857169470163" />
                                    <geom name="wrist_joint_l_geom" type="mesh" mesh="wrist_joint_l" pos="0 0 0" euler="0 0 0" />
                                    <inertial mass="0.16360616576335538" pos="-0.022760321024193456 0.035866581950933105 0.05131152865552535" fullinertia="0.00011514146451670215 0.00014583011440746213 9.679461264664965e-05 3.305366485096102e-06 -7.1462989612463515e-06 1.2645936324561897e-05" />
                                    <body name="servo_wrist_pitch_l" pos="0.008703848000054162 0.014499993211092282 0.03345434448437274" euler="-1.6081226496765745e-16 2.858824288409778e-15 1.5707963267948966">
                                        <geom name="servo_wrist_pitch_l_geom" type="mesh" mesh="servo_wrist_pitch_l" pos="0 0 0" euler="0 0 0" />
                                        <inertial mass="0.2574774645033229" pos="0.016612363704313352 0.033334638470363075 0.04754288849972697" fullinertia="4.43548630862447e-05 4.572278841338829e-05 7.311602559772343e-05 3.6130695128810534e-07 7.027404491500341e-09 8.37545818292404e-09" />
                                        <body name="hand_l" pos="0.01200000678890774 0.03345384800005428 0.0715456555156276" euler="-7.216449660063417e-16 1.7774556554708139e-16 -1.5707963267948963">
                                            <joint name="servo_wrist_pitch_l_Revolute_wrist_pitch_l" type="hinge" axis="1.000000000000001 -9.781345928005539e-17 2.0400348077486194e-15" pos="0.024750050104569998 0.014000407884749691 -0.024000142830530244" />
                                            <geom name="hand_l_geom" type="mesh" mesh="hand_l" pos="0 0 0" euler="0 0 0" />
                                            <geom name="hand_l_collision1" class="collision_geom" pos="0.027 0.047 -0.024" size="0.0015 0.04 0.01" />
                                            <geom name="hand_l_collision2" class="collision_geom" pos="0.036 0.0885 -0.024" size="0.0075 0.0015 0.01" />
                                            <geom name="hand_l_collision3" class="collision_geom" pos="0.045 0.085 -0.024" size="0.0015 0.005 0.01" />
                                            <inertial mass="0.017731524807570984" pos="0.007927371880112145 0.050554281775922055 -0.024000000000010215" fullinertia="1.153657478461265e-05 1.2648677821680533e-05 2.3032321428704974e-05 -4.718790043704748e-06 -7.041301883164844e-18 -6.786007111283571e-18" />
                                        </body>
                                    </body>
                                </body>
                            </body>
                        </body>
                    </body>
                </body>
            </body>
            <body name="servo_hip_roll_r" pos="-0.017249993211091948 0.2348961519999459 -0.006454344484372587" euler="3.141592653589792 -1.9672443966499903e-16 3.141592653589793">
                <geom name="servo_hip_roll_r_geom" type="mesh" mesh="servo_hip_roll_r" pos="0 0 0" euler="0 0 0" />
                <inertial mass="0.25164687718092266" pos="0.016295528106545536 0.03288647170678994 0.04754491271418351" fullinertia="4.143432390869137e-05 4.382264111655191e-05 6.936512928158031e-05 1.9005141956634593e-06 -1.0197049254412309e-10 -1.6884099916893918e-09" />
                <body name="hip_joint_r" pos="0.01600000678890807 0.008703848000054215 0.037545655515627434" euler="3.141592653589792 2.2204460492502657e-16 4.733165431326058e-30">
                    <joint name="servo_hip_roll_r_Revolute_hip_roll_r" type="hinge" axis="3.2033335732497615e-15 0.9999999999999991 1.2575275284524125e-16" pos="0.010000142830530722 -4.0885332704827e-07 -0.010000050104568566" />
                    <geom name="hip_joint_r_geom" type="mesh" mesh="hip_joint_r" pos="0 0 0" euler="0 0 0" />
                    <inertial mass="0.04536367978101096" pos="0.015679169150879912 0.013944636154283093 -0.0015204553499205504" fullinertia="2.3284052485714365e-05 1.7057494663980123e-05 7.86001945088333e-06 -9.022824967104283e-07 -6.427073886900483e-07 -9.576858047656247e-07" />
                    <body name="servo_hip_pitch_r" pos="0.04445384800005388 -0.027545655515627595 0.01600000678890865" euler="-1.5707963267948966 2.636779683484725e-15 1.5707963267948877">
                        <geom name="servo_hip_pitch_r_geom" type="mesh" mesh="servo_hip_pitch_r" pos="0 0 0" euler="0 0 0" />
                        <inertial mass="0.2574774645033229" pos="0.016612363704313533 0.033334638470363206 0.04754288849972691" fullinertia="4.4354863086260965e-05 4.5722788413391966e-05 7.311602559771131e-05 3.6130695128596166e-07 7.0274044847127516e-09 8.375458181901685e-09" />
                        <body name="knee_joint_r" pos="-0.014499993211091624 0.008703848000054358 0.03354565551562761" euler="-9.298117831235818e-16 1.583768546120587e-16 -1.5707963267948966">
                            <joint name="servo_hip_pitch_r_Revolute_hip_pitch_r" type="hinge" axis="1.000000000000001 1.9428902930940222e-16 -3.203333573249764e-15" pos="1.428305308452249e-07 0.04050005010456867 0.013999591146672853" />
                            <geom name="knee_joint_r_geom" type="mesh" mesh="knee_joint_r" pos="0 0 0" euler="0 0 0" />
                            <inertial mass="0.16360616576335538" pos="-0.02276032102419348 0.03586658195093318 0.05131152865552532" fullinertia="0.0001151414645167005 0.0001458301144074635 9.67946126466452e-05 3.305366485096118e-06 -7.146298961246862e-06 1.2645936324562965e-05" />
                            <body name="servo_knee_pitch_r" pos="0.008703848000054446 0.014499993211092157 0.033454344484373094" euler="7.822106558983417e-16 -1.2448375663609527e-14 1.5707963267948966">
                                <geom name="servo_knee_pitch_r_geom" type="mesh" mesh="servo_knee_pitch_r" pos="0 0 0" euler="0 0 0" />
                                <inertial mass="0.2574774645033229" pos="0.0166123637043134 0.033334638470363144 0.04754288849972702" fullinertia="4.435486308625019e-05 4.572278841338825e-05 7.311602559771137e-05 3.613069512850641e-07 7.027404486484428e-09 8.375458184319694e-09" />
                                <body name="ankle_joint_r" pos="-0.014499993211091767 0.008703848000054375 0.03354565551562729" euler="1.568190022283029e-15 -3.591217469734362e-17 -1.5707963267948972">
                                    <joint name="servo_knee_pitch_r_Revolute_knee_pitch_r" type="hinge" axis="0.9999999999999992 6.661338147750824e-16 -1.4083519214576268e-14" pos="1.428305315329825e-07 0.04050005010456824 0.013999591146672447" />
                                    <geom name="ankle_joint_r_geom" type="mesh" mesh="ankle_joint_r" pos="0 0 0" euler="0 0 0" />
                                    <inertial mass="0.16360616576335538" pos="-0.022760321024193387 0.03586658195093298 0.05131152865552525" fullinertia="0.00011514146451670163 0.00014583011440746056 9.679461264664648e-05 3.305366485096001e-06 -7.146298961246185e-06 1.2645936324562843e-05" />
                                    <body name="servo_ankle_pitch_r" pos="0.008703848000055654 0.014499993211091713 0.033454344484373434" euler="-1.1877685627459379e-15 -3.000204251701887e-14 1.5707963267948974">
                                        <geom name="servo_ankle_pitch_r_geom" type="mesh" mesh="servo_ankle_pitch_r" pos="0 0 0" euler="0 0 0" />
                                        <inertial mass="0.2574774645033229" pos="0.016612363704313446 0.033334638470363075 0.04754288849972691" fullinertia="4.435486308625457e-05 4.572278841338912e-05 7.31160255977121e-05 3.6130695128464564e-07 7.0274044860441244e-09 8.375458182583667e-09" />
                                        <body name="foot_r" pos="0.1346230568934768 0.05106499083058583 0.13620424666230074" euler="-1.5707963267948952 -5.551115123125905e-17 -1.762479051592462e-15">
                                            <joint name="servo_ankle_pitch_r_Revolute_ankle_pitch_r" type="hinge" axis="3.608224830031792e-16 4.206911236563043e-14 -0.9999999999999986" pos="-0.10862300000000047 0.088659000000001 -0.04236128566106423" />
                                            <geom name="foot_r_geom" type="mesh" mesh="foot_r" pos="0 0 0" euler="0 0 0" />
                                            <geom name="foot_r_collision1" class="collision_geom" pos="-0.0965 0.0315 -0.017" size="0.036 0.002 0.025" />
                                            <geom name="foot_r_collision2" class="collision_geom" pos="-0.062 0.026 -0.04" size="0.002 0.004 0.002" />
                                            <geom name="foot_r_collision3" class="collision_geom" pos="-0.062 0.026 0.006" size="0.002 0.004 0.002" />
                                            <inertial mass="0.03103773564018268" pos="-0.1023744092130386 0.045338918856236504 -0.016750979085956956" fullinertia="2.306410921035111e-05 1.967321129145183e-05 2.0404112815281717e-05 2.7301235006992727e-06 -2.7120355746764384e-08 1.8801607324658326e-07" />
                                        </body>
                                    </body>
                                </body>
                            </body>
                        </body>
                    </body>
                </body>
            </body>
            <body name="servo_hip_roll_l" pos="0.01724999321109182 0.23489615199994554 -0.10154565551562755" euler="-2.3894149132996725e-15 -5.273559366969514e-16 2.3665827156630365e-30">
                <geom name="servo_hip_roll_l_geom" type="mesh" mesh="servo_hip_roll_l" pos="0 0 0" euler="0 0 0" />
                <inertial mass="0.25164687718092266" pos="0.01629552810654556 0.03288647170679008 0.047544912714183804" fullinertia="4.143432390868802e-05 4.382264111655068e-05 6.93651292815772e-05 1.9005141956644042e-06 -1.0197049322623826e-10 -1.688409992522166e-09" />
                <body name="hip_joint_l" pos="0.016000006788908304 0.008703848000054179 0.05754565551562745" euler="2.3944671574003773e-15 3.4694469519535116e-16 -3.1554436208840423e-30">
                    <joint name="servo_hip_roll_l_Revolute_hip_roll_l" type="hinge" axis="5.02132377607343e-15 1.0000000000000002 2.435410355526055e-18" pos="0.009999857169469186 4.0885332681181735e-07 -0.010000050104569407" />
                    <geom name="hip_joint_l_geom" type="mesh" mesh="hip_joint_l" pos="0 0 0" euler="0 0 0" />
                    <inertial mass="0.04536367978101092" pos="0.015679169150879958 -0.013944636154283083 -0.0015204553499205042" fullinertia="2.328405248571436e-05 1.705749466398036e-05 7.860019450883357e-06 9.022824967104128e-07 -6.427073886900551e-07 9.576858047658342e-07" />
                    <body name="servo_hip_pitch_l" pos="0.0444538480000546 -0.06754565551562738 0.016000006788908082" euler="-1.5707963267948966 -8.187894806610614e-16 1.5707963267949054">
                        <geom name="servo_hip_pitch_l_geom" type="mesh" mesh="servo_hip_pitch_l" pos="0 0 0" euler="0 0 0" />
                        <inertial mass="0.2574774645033229" pos="0.01661236370431345 0.03333463847036315 0.04754288849972703" fullinertia="4.435486308625915e-05 4.5722788413381395e-05 7.311602559771174e-05 3.613069512844e-07 7.027404483835742e-09 8.375458182143567e-09" />
                        <body name="knee_joint_l" pos="-0.014499993211091695 0.008703848000054224 0.061545655515627476" euler="-3.1415926535897927 -9.142332592859252e-17 -1.5707963267948974">
                            <joint name="servo_hip_pitch_l_Revolute_hip_pitch_l" type="hinge" axis="0.999999999999999 1.318389841742371e-15 -5.053143722541764e-15" pos="1.42830531034208e-07 0.04050005010456955 0.01399959114667344" />
                            <geom name="knee_joint_l_geom" type="mesh" mesh="knee_joint_l" pos="0 0 0" euler="0 0 0" />
                            <inertial mass="0.16360616576335604" pos="0.02276032102419333 0.03586658195093294 0.05131152865586414" fullinertia="0.00011514146448919786 0.00014583011437149595 9.679461265510802e-05 -3.3053664850964597e-06 7.1462989610937975e-06 1.2645936324306226e-05" />
                            <body name="servo_knee_pitch_l" pos="-0.006203848000054153 0.014499993211091872 0.12854565551562766" euler="-3.141592653589793 -1.0310206686310455e-15 -1.570796326794898">
                                <geom name="servo_knee_pitch_l_geom" type="mesh" mesh="servo_knee_pitch_l" pos="0 0 0" euler="0 0 0" />
                                <inertial mass="0.2574774645033229" pos="0.016612363704313456 0.03333463847036306 0.04754288849972684" fullinertia="4.435486308625728e-05 4.572278841338829e-05 7.311602559771288e-05 3.6130695128474733e-07 7.027404484738669e-09 8.37545818087294e-09" />
                                <body name="ankle_joint_l" pos="-0.014499993211091678 0.008703848000054483 0.061545655515627455" euler="3.141592653589792 -8.130682919349429e-16 -1.570796326794893">
                                    <joint name="servo_knee_pitch_l_Revolute_knee_pitch_l" type="hinge" axis="1.0 -3.205768983605135e-15 -5.441721781160588e-15" pos="1.4283053125213125e-07 0.04050005010456944 0.013999591146673372" />
                                    <geom name="ankle_joint_l_geom" type="mesh" mesh="ankle_joint_l" pos="0 0 0" euler="0 0 0" />
                                    <inertial mass="0.16360616576335604" pos="0.022760321024193352 0.03586658195093297 0.05131152865586426" fullinertia="0.00011514146448919805 0.0001458301143714986 9.679461265510962e-05 -3.305366485096495e-06 7.146298961093559e-06 1.2645936324305634e-05" />
                                    <body name="servo_ankle_pitch_l" pos="-0.008703848000054321 0.014499993211091997 0.12854565551562774" euler="3.1415926535897922 -7.276025182147515e-15 -1.5707963267948928">
                                        <geom name="servo_ankle_pitch_l_geom" type="mesh" mesh="servo_ankle_pitch_l" pos="0 0 0" euler="0 0 0" />
                                        <inertial mass="0.2574774645033229" pos="0.016612363704313363 0.033334638470363234 0.04754288849972695" fullinertia="4.4354863086250556e-05 4.57227884133911e-05 7.311602559771174e-05 3.61306951285538e-07 7.027404484708254e-09 8.375458181285683e-09" />
                                        <body name="foot_l" pos="0.13462305689347726 0.05106499083058572 -0.04111293563104567" euler="1.5707963267948952 1.3877787807832181e-16 -9.436895709314083e-16">
                                            <joint name="servo_ankle_pitch_l_Revolute_ankle_pitch_l" type="hinge" axis="-1.9428902930940163e-16 1.9428902930940358e-16 -0.9999999999999992" pos="-0.10862299999999984 0.08865899999999982 0.042360999999999906" />
                                            <geom name="foot_l_geom" type="mesh" mesh="foot_l" pos="0 0 0" euler="0 0 0" />
                                            <geom name="foot_l_collision1" class="collision_geom" pos="-0.0959 0.0315 0.0165" size="0.036 0.002 0.025" />
                                            <geom name="foot_l_collision2" class="collision_geom" pos="-0.062 0.026 0.0395" size="0.002 0.004 0.002" />
                                            <geom name="foot_l_collision3" class="collision_geom" pos="-0.062 0.026 -0.0065" size="0.002 0.004 0.002" />
                                            <inertial mass="0.0310377356401822" pos="-0.10237440921308003 0.045338918856236456 0.016750979085957036" fullinertia="2.306410921485705e-05 1.9673211289964826e-05 2.040411281830145e-05 2.730123500753741e-06 2.7120355748187906e-08 -1.8801607324644808e-07" />
                                        </body>
                                    </body>
                                </body>
                            </body>
                        </body>
                    </body>
                </body>
            </body>
        </body>
    </worldbody>

    <actuator>
        <!-- Right Arm -->
        <position name="shoulder_roll_r"        joint="servo_shoulder_roll_r_Revolute_shoulder_roll_r"/>
        <position name="shoulder_pitch_r"       joint="servo_shoulder_pitch_r_Revolute_shoulder_pitch_r" />
        <position name="elbow_pitch_r"          joint="servo_elbow_pitch_r_Revolute_elbow_pitch_r" />
        <position name="wrist_pitch_r"          joint="servo_wrist_pitch_r_Revolute_wrist_pitch_r" />

        <!-- Left Arm -->
        <position name="shoulder_roll_l" joint="servo_shoulder_roll_l_Revolute_shoulder_roll_l"/>
        <position name="shoulder_pitch_l"          joint="servo_shoulder_pitch_l_Revolute_shoulder_pitch_l" />
        <position name="elbow_pitch_l"          joint="servo_elbow_pitch_l_Revolute_elbow_pitch_l" />
        <position name="wrist_pitch_l"          joint="servo_wrist_pitch_l_Revolute_wrist_pitch_l" />

        <!-- Right Leg -->
        <position name="hip_roll_r"   joint="servo_hip_roll_r_Revolute_hip_roll_r" />
        <position name="hip_pitch_r"  joint="servo_hip_pitch_r_Revolute_hip_pitch_r"/>
        <position name="knee_pitch_r" joint="servo_knee_pitch_r_Revolute_knee_pitch_r" />
        <position name="ankle_pitch_r" joint="servo_ankle_pitch_r_Revolute_ankle_pitch_r" />

        <!-- Left Leg -->
        <position name="hip_roll_l"   joint="servo_hip_roll_l_Revolute_hip_roll_l" />
        <position name="hip_pitch_l"  joint="servo_hip_pitch_l_Revolute_hip_pitch_l" />
        <position name="knee_pitch_l" joint="servo_knee_pitch_l_Revolute_knee_pitch_l" />
        <position name="ankle_pitch_l" joint="servo_ankle_pitch_l_Revolute_ankle_pitch_l" />
    </actuator>

</mujoco>