<mujoco model="Robot_V3">
    
    <include file="wall.xml"/>
    <include file="groundplane.xml"/>
    <include file="route_ladder_V1.xml"/>

    <option gravity="0 0 -9.81"/>
    <statistic center="0 0 0.2" extent="0.6"/>
    <compiler angle="radian" autolimits="true"/>

    <visual>
        <headlight diffuse="0.6 0.6 0.6" ambient="0.3 0.3 0.3" specular="0 0 0"/>
        <rgba haze="0.15 0.25 0.35 1"/>
        <global azimuth="160" elevation="-20"/>
    </visual>

    <default>
        <position kp="21.1" ctrlrange="-1.5708 1.5708" forcerange="-5 5"/>
        <joint damping="1.084" armature="0.045" frictionloss="0.03"/>
        <geom solref="0.004 1" conaffinity="0" contype="0" />
        <default class="collision_geom">
            <geom type="box" contype="1" conaffinity="1" solimp="0.99 0.99 0.01" solref="0.01 1" rgba="1 0 0 0.3"/>
        </default>
    </default>

    <asset>
        <mesh name="servo_shoulder_roll_r" file="meshes/servo_shoulder_roll_r.stl" scale="0.001 0.001 0.001" />
        <mesh name="servo_shoulder_roll_l" file="meshes/servo_shoulder_roll_l.stl" scale="0.001 0.001 0.001" />
        <mesh name="Chest" file="meshes/Chest.stl" scale="0.001 0.001 0.001" />
        <mesh name="servo_hip_roll_l" file="meshes/servo_hip_roll_l.stl" scale="0.001 0.001 0.001" />
        <mesh name="servo_hip_roll_r" file="meshes/servo_hip_roll_r.stl" scale="0.001 0.001 0.001" />
        <mesh name="servo_hip_pitch_r" file="meshes/servo_hip_pitch_r.stl" scale="0.001 0.001 0.001" />
        <mesh name="servo_hip_pitch_l" file="meshes/servo_hip_pitch_l.stl" scale="0.001 0.001 0.001" />
        <mesh name="knee_joint_r" file="meshes/knee_joint_r.stl" scale="0.001 0.001 0.001" />
        <mesh name="knee_joint_l" file="meshes/knee_joint_l.stl" scale="0.001 0.001 0.001" />
        <mesh name="servo_knee_pitch_r" file="meshes/servo_knee_pitch_r.stl" scale="0.001 0.001 0.001" />
        <mesh name="servo_knee_pitch_l" file="meshes/servo_knee_pitch_l.stl" scale="0.001 0.001 0.001" />
        <mesh name="servo_ankle_pitch_r" file="meshes/servo_ankle_pitch_r.stl" scale="0.001 0.001 0.001" />
        <mesh name="servo_ankle_pitch_l" file="meshes/servo_ankle_pitch_l.stl" scale="0.001 0.001 0.001" />
        <mesh name="foot_l" file="meshes/foot_l.stl" scale="0.001 0.001 0.001" />
        <mesh name="servo_shoulder_pitch_r" file="meshes/servo_shoulder_pitch_r.stl" scale="0.001 0.001 0.001" />
        <mesh name="elbow_joint_r" file="meshes/elbow_joint_r.stl" scale="0.001 0.001 0.001" />
        <mesh name="servo_elbow_pitch_r" file="meshes/servo_elbow_pitch_r.stl" scale="0.001 0.001 0.001" />
        <mesh name="servo_wrist_pitch_r" file="meshes/servo_wrist_pitch_r.stl" scale="0.001 0.001 0.001" />
        <mesh name="ankle_joint_l" file="meshes/ankle_joint_l.stl" scale="0.001 0.001 0.001" />
        <mesh name="ankle_joint_r" file="meshes/ankle_joint_r.stl" scale="0.001 0.001 0.001" />
        <mesh name="wrist_joint_r" file="meshes/wrist_joint_r.stl" scale="0.001 0.001 0.001" />
        <mesh name="shoulder_joint_l" file="meshes/shoulder_joint_l.stl" scale="0.001 0.001 0.001" />
        <mesh name="hip_joint_l" file="meshes/hip_joint_l.stl" scale="0.001 0.001 0.001" />
        <mesh name="hip_joint_r" file="meshes/hip_joint_r.stl" scale="0.001 0.001 0.001" />
        <mesh name="hand_r" file="meshes/hand_r.stl" scale="0.001 0.001 0.001" />
        <mesh name="servo_shoulder_pitch_l" file="meshes/servo_shoulder_pitch_l.stl" scale="0.001 0.001 0.001" />
        <mesh name="elbow_joint_l" file="meshes/elbow_joint_l.stl" scale="0.001 0.001 0.001" />
        <mesh name="servo_elbow_pitch_l" file="meshes/servo_elbow_pitch_l.stl" scale="0.001 0.001 0.001" />
        <mesh name="wrist_joint_l" file="meshes/wrist_joint_l.stl" scale="0.001 0.001 0.001" />
        <mesh name="servo_wrist_pitch_l" file="meshes/servo_wrist_pitch_l.stl" scale="0.001 0.001 0.001" />
        <mesh name="hand_l" file="meshes/hand_l.stl" scale="0.001 0.001 0.001" />
        <mesh name="shoulder_joint_r" file="meshes/shoulder_joint_r.stl" scale="0.001 0.001 0.001" />
        <mesh name="foot_r" file="meshes/foot_r.stl" scale="0.001 0.001 0.001" />
    </asset>
    <worldbody>
        
        <light directional="true" pos="-0.5 0.5 3" dir="0 0 -1" />

        <body name="chest" pos="0 -0.08 0.42" euler="0 -1.5708 0">
            <freejoint/>
            <geom name="Chest_geom" type="mesh" mesh="Chest" pos="0 0 0" euler="0 0 0" />
            <inertial mass="0.7952514053524476" pos="-0.006346473245278406 0.035707372495725906 -0.007043995404605305" fullinertia="0.0014662922767373424 0.0022847010920096474 0.0010035139687291856 -6.208877224979679e-05 -1.0166713500872242e-16 6.11802758271659e-17" />
            <body name="servo_shoulder_roll_r" pos="0.007249988124203988 -0.023941384913986653 0.07805985259544226" euler="-1.5707963267948952 -2.636779683484818e-16 -1.1166932987967645e-16">
                <geom name="servo_shoulder_roll_r_geom" type="mesh" mesh="servo_shoulder_roll_r" pos="0 0 0" euler="0 0 0" />
                <inertial mass="0.25164687718092266" pos="0.016295528106545568 0.03288647170679023 0.047544912714183846" fullinertia="4.14343239086837e-05 4.382264111655821e-05 6.93651292815773e-05 1.9005141956630229e-06 -1.0197049298111878e-10 -1.6884099913441885e-09" />
                <body name="shoulder_joint_r" pos="0.026000006788908403 -0.012546145327644278 -0.020204342316568005" euler="2.2204460492503303e-16 -1.5707963267948812 0">
                    <joint name="servo_shoulder_roll_r_Revolute_shoulder_roll_r" type="hinge" axis="1.0269562977781564e-15 -1.0000000000000018 5.407891666751807e-14" pos="0.06774994772762644 0.021249850497157934 -4.0788475014128133e-07" />
                    <geom name="shoulder_joint_r_geom" type="mesh" mesh="shoulder_joint_r" pos="0 0 0" euler="0 0 0" />
                    <inertial mass="0.013004386860980393" pos="0.0680837468028471 2.7323225165759602e-05 -1.7851939050344695e-14" fullinertia="5.276273904760669e-06 8.369185492904745e-06 1.2786255215626321e-05 1.118787860083246e-07 -5.54381827848958e-18 -3.63877545271867e-18" />
                    <body name="servo_shoulder_pitch_r" pos="0.1022038458322508 -0.0732956621879287 0.02600000678890808" euler="-1.5707963267948963 -1.7923089732338163e-14 1.5707963267948961">
                        <joint name="shoulder_joint_r_Revolute_shoulder_pitch_r" type="hinge" axis="8.15503713203168e-16 -1.0000000000000024 -1.689613343456003e-14" pos="0.0260004146736558 0.008703898104623645 0.04754551268508693" />
                        <geom name="servo_shoulder_pitch_r_geom" type="mesh" mesh="servo_shoulder_pitch_r" pos="0 0 0" euler="0 0 0" />
                        <inertial mass="0.2574774645033229" pos="0.01661236370431332 0.03333463847036317 0.04754288849972699" fullinertia="4.4354863086248754e-05 4.572278841339186e-05 7.31160255977166e-05 3.613069512842415e-07 7.027404485394572e-09 8.37545818182197e-09" />
                        <body name="elbow_joint_r" pos="0.04600000678890694 0.030103848000053262 -0.00845434448437251" euler="-1.9345636204093226e-14 7.138904121942916e-15 3.141592653589793">
                            <geom name="elbow_joint_r_geom" type="mesh" mesh="elbow_joint_r" pos="0 0 0" euler="0 0 0" />
                            <inertial mass="0.0940156941457831" pos="0.03024999999999565 0.0025000000000000096 0.03600000000000013" fullinertia="3.8135788919557435e-05 7.54391394245418e-05 3.767401128966516e-05 1.2854632873936593e-21 -4.061822523841726e-19 -8.73742279168719e-21" />
                            <body name="servo_elbow_pitch_r" pos="0.0460000067889084 0.030103848000053085 -0.03154565551562863" euler="-3.0239699633227626e-14 -3.0190985971211267e-17 3.141592653589793">
                                <geom name="servo_elbow_pitch_r_geom" type="mesh" mesh="servo_elbow_pitch_r" pos="0 0 0" euler="0 0 0" />
                                <inertial mass="0.2574774645033229" pos="0.016612363704313404 0.03333463847036313 0.047542888499726994" fullinertia="4.435486308625187e-05 4.5722788413377926e-05 7.311602559770963e-05 3.61306951284666e-07 7.027404484337381e-09 8.375458181830911e-09" />
                                <body name="wrist_joint_r" pos="-0.0144999932110915 0.008703848000054313 0.061545655515627774" euler="-3.1415926535897927 6.123233995734226e-17 -1.5707963267948968">
                                    <joint name="servo_elbow_pitch_r_Revolute_elbow_pitch_r" type="hinge" axis="1.0000000000000036 -8.155037132031786e-16 -5.627369734614612e-15" pos="5.0104570946194273e-08 0.04050040788474662 0.014000142830540536" />
                                    <geom name="wrist_joint_r_geom" type="mesh" mesh="wrist_joint_r" pos="0 0 0" euler="0 0 0" />
                                    <inertial mass="0.2138444469189373" pos="0.024312945201467564 0.033387953347823504 0.05311811492378441" fullinertia="0.00013956317461262627 0.00016881014969251265 0.00013951676965105237 -6.219365998040075e-07 5.193177317477631e-06 1.5763238779509977e-05" />
                                    <body name="servo_wrist_pitch_r" pos="-0.008703848000054375 0.014499993211092316 0.128545655515628" euler="-3.141592653589793 -9.28424004342787e-15 -1.5707963267948968">
                                        <geom name="servo_wrist_pitch_r_geom" type="mesh" mesh="servo_wrist_pitch_r" pos="0 0 0" euler="0 0 0" />
                                        <inertial mass="0.2574774645033229" pos="0.0166123637043133 0.03333463847036319 0.04754288849972694" fullinertia="4.435486308624812e-05 4.5722788413409205e-05 7.31160255977199e-05 3.6130695128418337e-07 7.0274044878479555e-09 8.375458182146955e-09" />
                                        <body name="hand_r" pos="0.01200000678890806 0.033453848000054257 0.07154565551562744" euler="2.4980018054065534e-16 -5.417030312083842e-16 -1.5707963267948963">
                                            <joint name="servo_wrist_pitch_r_Revolute_wrist_pitch_r" type="hinge" axis="1.0000000000000004 1.8602326221243043e-28 3.906670489353941e-15" pos="0.024749949895428166 0.01400040788474306 -0.02400014283053983" />
                                            <geom name="hand_r_geom" type="mesh" mesh="hand_r" pos="0 0 0" euler="0 0 0" />
                                            <geom name="hand_r_collision1" class="collision_geom" pos="0.027 0.047 -0.024" size="0.0015 0.04 0.01" />
                                            <geom name="hand_r_collision2" class="collision_geom" pos="0.036 0.0885 -0.024" size="0.0075 0.0015 0.01" />
                                            <geom name="hand_r_collision3" class="collision_geom" pos="0.045 0.085 -0.024" size="0.0015 0.005 0.01" />
                                            <inertial mass="0.017731524807570984" pos="0.00792737188011213 0.05055428177592213 -0.024000000000010152" fullinertia="1.1536574784612202e-05 1.2648677821680458e-05 2.3032321428704073e-05 -4.718790043704896e-06 -7.08441902579627e-18 -6.4628214751042465e-18" />
                                        </body>
                                    </body>
                                </body>
                            </body>
                        </body>
                    </body>
                </body>
            </body>
            <body name="servo_shoulder_roll_l" pos="0.00724998812420381 0.07114992611726857 -0.09214784340466654" euler="1.570796326794895 -1.1102230246250643e-16 1.1166932987967635e-16">
                <geom name="servo_shoulder_roll_l_geom" type="mesh" mesh="servo_shoulder_roll_l" pos="0 0 0" euler="0 0 0" />
                <inertial mass="0.25164687718092266" pos="0.016295528106545595 0.03288647170679025 0.04754491271418394" fullinertia="4.1434323908683604e-05 4.3822641116555056e-05 6.936512928156703e-05 1.900514195660785e-06 -1.019704929380948e-10 -1.688409991077253e-09" />
                <body name="shoulder_joint_l" pos="0.026000006788908826 -0.012546145327643999 0.11529565334782298" euler="-2.3592239273283886e-16 1.5707963267948966 0">
                    <joint name="servo_shoulder_roll_l_Revolute_shoulder_roll_l" type="hinge" axis="-1.16573417585653e-15 1.000000000000001 -3.8906378119206933e-14" pos="0.06774994772762655 0.021250136158239306 4.0788475550354824e-07" />
                    <geom name="shoulder_joint_l_geom" type="mesh" mesh="shoulder_joint_l" pos="0 0 0" euler="0 0 0" />
                    <inertial mass="0.013004386860980393" pos="0.0680837468028471 2.732322516576015e-05 -1.7844591190078124e-14" fullinertia="5.276273904760669e-06 8.369185492904515e-06 1.2786255215626155e-05 1.118787860083243e-07 -5.54002813018847e-18 -3.6228116727759506e-18" />
                    <body name="servo_shoulder_pitch_l" pos="0.10220384583225073 0.021795648843326135 -0.026000006788908365" euler="1.5707963267948963 -1.7319479184152373e-14 1.5707963267948966">
                        <joint name="shoulder_joint_l_Revolute_shoulder_pitch_l" type="hinge" axis="3.9101346897439e-16 -1.0000000000000024 -1.8485213360008976e-14" pos="0.026000414673665755 0.008703898104623483 0.0475455126850872" />
                        <geom name="servo_shoulder_pitch_l_geom" type="mesh" mesh="servo_shoulder_pitch_l" pos="0 0 0" euler="0 0 0" />
                        <inertial mass="0.2574774645033229" pos="0.016612363704313404 0.03333463847036318 0.04754288849972725" fullinertia="4.435486308624661e-05 4.572278841338839e-05 7.311602559771001e-05 3.6130695128474585e-07 7.027404485852447e-09 8.375458181976862e-09" />
                        <body name="elbow_joint_l" pos="-0.014499993211091394 0.030103848000053487 0.10354565551562753" euler="-3.1415926535897762 -5.689893001204008e-16 -1.8041124150159612e-16">
                            <geom name="elbow_joint_l_geom" type="mesh" mesh="elbow_joint_l" pos="0 0 0" euler="0 0 0" />
                            <inertial mass="0.0940156941457831" pos="0.030249999999995537 0.0025000000000000113 0.036000000000000046" fullinertia="3.813578891955677e-05 7.543913942454329e-05 3.7674011289666825e-05 2.144335307565923e-20 -1.2729847342044966e-20 5.0377121886458184e-20" />
                            <body name="servo_elbow_pitch_l" pos="0.014499993211091678 0.030103848000054164 0.06354565551562728" euler="-3.141592653589792 -7.216449660063579e-16 -2.2204460492502874e-16">
                                <geom name="servo_elbow_pitch_l_geom" type="mesh" mesh="servo_elbow_pitch_l" pos="0 0 0" euler="0 0 0" />
                                <inertial mass="0.2574774645033229" pos="0.016612363704313318 0.03333463847036302 0.04754288849972694" fullinertia="4.435486308624996e-05 4.572278841338123e-05 7.311602559771305e-05 3.6130695128480445e-07 7.027404482369507e-09 8.375458181819185e-09" />
                                <body name="wrist_joint_l" pos="-0.014499993211092068 0.11970384512458715 0.09254565574378955" euler="-3.1415926535897913 -7.754553812077063e-17 -1.5707963267948966">
                                    <joint name="servo_elbow_pitch_l_Revolute_elbow_pitch_l" type="hinge" axis="1.0000000000000016 1.6409804333819326e-16 1.7208456881688674e-15" pos="-0.11099994701996421 0.04050040788475895 0.04500014305870255" />
                                    <geom name="wrist_joint_l_geom" type="mesh" mesh="wrist_joint_l" pos="0 0 0" euler="0 0 0" />
                                    <inertial mass="0.2138444469189371" pos="-0.08668705192306547 0.03338795334782358 0.005881885304377455" fullinertia="0.00013956317461262567 0.00016881014969250804 0.00013951676965104955 -6.21936599802336e-07 -5.1931773174775575e-06 -1.576323877950747e-05" />
                                    <body name="servo_wrist_pitch_l" pos="-0.11970384512458684 0.014499993211092424 0.02554565574378909" euler="-3.141592653589793 -1.040834085586084e-15 -1.570796326794897">
                                        <geom name="servo_wrist_pitch_l_geom" type="mesh" mesh="servo_wrist_pitch_l" pos="0 0 0" euler="0 0 0" />
                                        <inertial mass="0.2574774645033229" pos="0.016612363704313297 0.03333463847036306 0.047542888499726946" fullinertia="4.43548630862447e-05 4.572278841340217e-05 7.311602559771996e-05 3.613069512846089e-07 7.027404485819767e-09 8.3754581811193e-09" />
                                        <body name="hand_l" pos="0.012000006788908096 0.03345384800005428 0.07154565551562754" euler="-7.216449660063417e-16 1.777455655470877e-16 -1.5707963267948963">
                                            <joint name="servo_wrist_pitch_l_Revolute_wrist_pitch_l" type="hinge" axis="1.000000000000001 1.3877787807822274e-16 2.04003480774861e-15" pos="0.02474994989543123 0.014000407884761137 -0.024000142830541044" />
                                            <geom name="hand_l_geom" type="mesh" mesh="hand_l" pos="0 0 0" euler="0 0 0" />
                                            <geom name="hand_l_collision1" class="collision_geom" pos="0.027 0.047 -0.024" size="0.0015 0.04 0.01" />
                                            <geom name="hand_l_collision2" class="collision_geom" pos="0.036 0.0885 -0.024" size="0.0075 0.0015 0.01" />
                                            <geom name="hand_l_collision3" class="collision_geom" pos="0.045 0.085 -0.024" size="0.0015 0.005 0.01" />
                                            <inertial mass="0.017731524807570984" pos="0.007927371880112149 0.050554281775922 -0.02400000000001022" fullinertia="1.1536574784612219e-05 1.2648677821680425e-05 2.303232142870454e-05 -4.718790043704877e-06 -7.088961116173281e-18 -6.982236114352469e-18" />
                                        </body>
                                    </body>
                                </body>
                            </body>
                        </body>
                    </body>
                </body>
            </body>
            <body name="servo_hip_roll_r" pos="-0.08010385405551744 -0.023941384913986476 0.005205997806479772" euler="-1.5707963267948961 -9.436895709313813e-16 -1.5707963267948966">
                <geom name="servo_hip_roll_r_geom" type="mesh" mesh="servo_hip_roll_r" pos="0 0 0" euler="0 0 0" />
                <inertial mass="0.25164687718092266" pos="0.016295528106545523 0.03288647170678997 0.04754491271418353" fullinertia="4.143432390868633e-05 4.3822641116552535e-05 6.936512928157164e-05 1.9005141956633469e-06 -1.0197049240363146e-10 -1.6884099917532535e-09" />
                <body name="hip_joint_r" pos="0.026000006788908313 0.0037038480000542153 0.0475456555156275" euler="-5.134781488891346e-16 -2.498001805406606e-16 -1.5707963267948994">
                    <joint name="servo_hip_roll_r_Revolute_hip_roll_r" type="hinge" axis="-0.9999999999999996 3.7757991178111025e-14 -7.240803763619311e-16" pos="-0.005000408853327085 1.4283053661127782e-07 -5.010456935129606e-08" />
                    <geom name="hip_joint_r_geom" type="mesh" mesh="hip_joint_r" pos="0 0 0" euler="0 0 0" />
                    <inertial mass="0.013004386860980387" pos="0.016222670102532855 0.0003337489706512356 -1.77828756997368e-14" fullinertia="8.369185492904518e-06 5.276273904760447e-06 1.2786255215626121e-05 -1.1187878600836213e-07 3.6138960092586464e-18 -5.551165516107301e-18" />
                    <body name="servo_hip_pitch_r" pos="-0.005545655515627566 0.03445384800005389 -0.026000006788908358" euler="-3.141592653589793 1.5707963267948915 0">
                        <joint name="hip_joint_r_Revolute_hip_pitch_r" type="hinge" axis="-2.081668171173061e-16 -1.0000000000000036 4.1143560001271465e-14" pos="0.02599995668433922 0.008703705169519207 0.04754524666230148" />
                        <geom name="servo_hip_pitch_r_geom" type="mesh" mesh="servo_hip_pitch_r" pos="0 0 0" euler="0 0 0" />
                        <inertial mass="0.2574774645033229" pos="0.016612363704313547 0.03333463847036322 0.04754288849972687" fullinertia="4.435486308625576e-05 4.5722788413388496e-05 7.311602559771227e-05 3.613069512851488e-07 7.027404485694565e-09 8.375458180705502e-09" />
                        <body name="knee_joint_r" pos="-0.01449999321109157 0.025103848000054246 0.031545655515627435" euler="-7.243593833732838e-15 1.2351231148954813e-15 1.249000902703176e-16">
                            <geom name="knee_joint_r_geom" type="mesh" mesh="knee_joint_r" pos="0 0 0" euler="0 0 0" />
                            <inertial mass="0.0940156941457831" pos="0.030249999999995718 0.0025 0.03600000000000008" fullinertia="3.813578891955803e-05 7.543913942454017e-05 3.7674011289665646e-05 4.473895021059485e-20 4.2095279523606946e-19 -1.2572996629101751e-20" />
                            <body name="servo_knee_pitch_r" pos="0.01449999321109186 -0.025103848000054663 0.008454344484372883" euler="-5.800915303666444e-15 -1.0963452368173419e-15 4.163336342342771e-17">
                                <geom name="servo_knee_pitch_r_geom" type="mesh" mesh="servo_knee_pitch_r" pos="0 0 0" euler="0 0 0" />
                                <inertial mass="0.2574774645033229" pos="0.016612363704313404 0.03333463847036315 0.047542888499727036" fullinertia="4.435486308625149e-05 4.5722788413387385e-05 7.31160255977127e-05 3.613069512844546e-07 7.0274044856552536e-09 8.375458183837658e-09" />
                                <body name="ankle_joint_r" pos="-0.014499993211091718 0.0087038480000542 0.033545655515627215" euler="3.2474023470285837e-15 1.3045120539345591e-15 -1.5707963267948968">
                                    <joint name="servo_knee_pitch_r_Revolute_knee_pitch_r" type="hinge" axis="-0.999999999999999 8.326672684689688e-16 -3.134645321090074e-14" pos="1.428305336393713e-07 0.04049994989543057 0.013999591146673863" />
                                    <geom name="ankle_joint_r_geom" type="mesh" mesh="ankle_joint_r" pos="0 0 0" euler="0 0 0" />
                                    <inertial mass="0.2138444469189369" pos="-0.024312945201467463 0.033387953347823504 0.05311811492352507" fullinertia="0.00013956317464031452 0.0001688101497286753 0.00013951676964258882 6.219365998020341e-07 -5.193177317543746e-06 1.5763238779904457e-05" />
                                    <body name="servo_ankle_pitch_r" pos="0.008703848000055487 0.014499993211091633 0.033454344484373504" euler="1.5265566588595451e-16 -3.1681254841764453e-14 1.570796326794896">
                                        <geom name="servo_ankle_pitch_r_geom" type="mesh" mesh="servo_ankle_pitch_r" pos="0 0 0" euler="0 0 0" />
                                        <inertial mass="0.2574774645033229" pos="0.016612363704313435 0.033334638470363095 0.04754288849972691" fullinertia="4.435486308625435e-05 4.5722788413389554e-05 7.311602559771263e-05 3.6130695128481536e-07 7.027404485919681e-09 8.37545818242689e-09" />
                                        <body name="foot_r" pos="0.13462305689347837 0.051064990830583745 0.1362042466623009" euler="-1.5707963267948952 2.1558950229753837e-14 2.359223927327914e-16">
                                            <joint name="servo_ankle_pitch_r_Revolute_ankle_pitch_r" type="hinge" axis="2.148281552649682e-14 -1.2954128213751924e-15 -1.0000000000000029" pos="-0.10862310020913932 0.08865900000000042 -0.042361285661064015" />
                                            <geom name="foot_r_geom" type="mesh" mesh="foot_r" pos="0 0 0" euler="0 0 0" />
                                            <geom name="foot_r_collision1" class="collision_geom" pos="-0.0965 0.0315 -0.017" size="0.036 0.002 0.025" />
                                            <geom name="foot_r_collision2" class="collision_geom" pos="-0.062 0.026 -0.017" size="0.002 0.004 0.025" />
                                            <inertial mass="0.03234169397496026" pos="-0.10074037993738615 0.04455270352358194 -0.0167453411422271" fullinertia="2.3725983791337146e-05 2.1909544466948042e-05 2.2944028515995347e-05 3.7189633488188533e-06 -3.421237079960824e-08 1.9142840560623723e-07" />
                                        </body>
                                    </body>
                                </body>
                            </body>
                        </body>
                    </body>
                </body>
            </body>
            <body name="servo_hip_roll_l" pos="-0.08010385405551755 0.07114992611726847 -0.019293988615703965" euler="1.5707963267948961 2.0955459589799838e-15 -1.5707963267948952">
                <geom name="servo_hip_roll_l_geom" type="mesh" mesh="servo_hip_roll_l" pos="0 0 0" euler="0 0 0" />
                <inertial mass="0.25164687718092266" pos="0.016295528106545568 0.03288647170679012 0.04754491271418381" fullinertia="4.143432390868264e-05 4.382264111654954e-05 6.936512928157199e-05 1.9005141956651671e-06 -1.0197049326206498e-10 -1.6884099898755926e-09" />
                <body name="hip_joint_l" pos="0.026000006788907754 0.003703848000054073 0.047545655515627575" euler="1.37390099297364e-15 7.632783294297911e-16 -1.570796326794942">
                    <joint name="servo_hip_roll_l_Revolute_hip_roll_l" type="hinge" axis="-0.9999999999999998 -8.308631560538501e-14 1.0155139203260282e-15" pos="-0.00500040885333014 -1.4283053661936288e-07 5.010456919272503e-08" />
                    <geom name="hip_joint_l_geom" type="mesh" mesh="hip_joint_l" pos="0 0 0" euler="0 0 0" />
                    <inertial mass="0.013004386860980387" pos="0.016222670102532855 0.0003337489706512443 -1.7783877573231293e-14" fullinertia="8.369185492904542e-06 5.276273904760477e-06 1.2786255215626033e-05 -1.1187878600832432e-07 3.6123935988173194e-18 -5.549865280722952e-18" />
                    <body name="servo_hip_pitch_l" pos="0.08954565551562717 0.03445384800005577 0.02600000678890838" euler="-3.141592653589793 -1.5707963267948672 0">
                        <joint name="hip_joint_l_Revolute_hip_pitch_l" type="hinge" axis="4.718447854657679e-16 -1.0000000000000018 5.4875799049200164e-14" pos="0.025999956684339322 0.008703990830587113 0.04754606436895963" />
                        <geom name="servo_hip_pitch_l_geom" type="mesh" mesh="servo_hip_pitch_l" pos="0 0 0" euler="0 0 0" />
                        <inertial mass="0.2574774645033229" pos="0.016612363704313474 0.03333463847036314 0.04754288849972701" fullinertia="4.4354863086253944e-05 4.572278841339007e-05 7.311602559771261e-05 3.613069512842378e-07 7.027404485086479e-09 8.37545818098516e-09" />
                        <body name="knee_joint_l" pos="-0.014499993211091647 0.025103848000055076 -0.008454344484372616" euler="1.2307973102188665e-14 -2.498001805406496e-16 -1.5265566588598124e-16">
                            <geom name="knee_joint_l_geom" type="mesh" mesh="knee_joint_l" pos="0 0 0" euler="0 0 0" />
                            <inertial mass="0.0940156941457831" pos="0.03024999999999578 0.0025000000000000386 0.0360000000000002" fullinertia="3.813578891955883e-05 7.543913942454323e-05 3.767401128966643e-05 6.260864038633656e-20 -1.9068093525860453e-20 2.8276754844989183e-19" />
                            <body name="servo_knee_pitch_l" pos="0.014499993211091789 -0.02510384800005449 -0.031545655515627116" euler="-3.602687309886997e-15 8.60422844084485e-16 6.938893903907782e-17">
                                <geom name="servo_knee_pitch_l_geom" type="mesh" mesh="servo_knee_pitch_l" pos="0 0 0" euler="0 0 0" />
                                <inertial mass="0.2574774645033229" pos="0.016612363704313463 0.03333463847036306 0.047542888499726835" fullinertia="4.4354863086258146e-05 4.572278841339046e-05 7.311602559771202e-05 3.613069512846394e-07 7.027404485811074e-09 8.375458180665349e-09" />
                                <body name="ankle_joint_l" pos="-0.014499993211091598 0.008703848000054358 0.06154565551562742" euler="3.1415926535897896 3.0531133177191726e-16 -1.5707963267948968">
                                    <joint name="servo_knee_pitch_l_Revolute_knee_pitch_l" type="hinge" axis="0.9999999999999987 -9.714451465479188e-17 6.002212723820447e-14" pos="1.428305301040551e-07 0.04049994989543073 0.01399959114666769" />
                                    <geom name="ankle_joint_l_geom" type="mesh" mesh="ankle_joint_l" pos="0 0 0" euler="0 0 0" />
                                    <inertial mass="0.2138444469189373" pos="0.024312945201467345 0.03338795334782341 0.0531181149237841" fullinertia="0.00013956317461261776 0.00016881014969251596 0.0001395167696510522 -6.219365998039609e-07 5.1931773174776905e-06 1.576323877950797e-05" />
                                    <body name="servo_ankle_pitch_l" pos="-0.008703848000054039 0.01449999321109174 0.1285456555156279" euler="-3.141592653589793 -9.415384058194934e-15 -1.570796326794896">
                                        <geom name="servo_ankle_pitch_l_geom" type="mesh" mesh="servo_ankle_pitch_l" pos="0 0 0" euler="0 0 0" />
                                        <inertial mass="0.2574774645033229" pos="0.016612363704313387 0.03333463847036322 0.047542888499726946" fullinertia="4.435486308624969e-05 4.5722788413393375e-05 7.311602559771131e-05 3.6130695128537583e-07 7.027404485374084e-09 8.37545818064441e-09" />
                                        <body name="foot_l" pos="0.13462305689347762 0.05106499083058528 -0.041112935631045615" euler="1.5707963267948952 -7.025106852471869e-15 1.1657341758563806e-15">
                                            <joint name="servo_ankle_pitch_l_Revolute_ankle_pitch_l" type="hinge" axis="-6.9111383282915174e-15 -6.758304774927372e-14 -1.0000000000000018" pos="-0.10862310020913833 0.08865900000000551 0.04236100000000598" />
                                            <geom name="foot_l_geom" type="mesh" mesh="foot_l" pos="0 0 0" euler="0 0 0" />
                                            <geom name="foot_l_collision1" class="collision_geom" pos="-0.0959 0.0315 0.0165" size="0.036 0.002 0.025" />
                                            <geom name="foot_l_collision2" class="collision_geom" pos="-0.062 0.026 0.0165" size="0.002 0.004 0.025" />
                                            <inertial mass="0.03234169397495974" pos="-0.10074037993742484 0.044552703523581566 0.01674534114222712" fullinertia="2.3725983795842433e-05 2.190954446546569e-05 2.2944028519021294e-05 3.7189633488743382e-06 3.421237080126924e-08 -1.9142840560621944e-07" />
                                        </body>
                                    </body>
                                </body>
                            </body>
                        </body>
                    </body>
                </body>
            </body>
        </body>
    </worldbody>

    <actuator>
        <!-- Right Arm -->
        <position name="shoulder_roll_r" joint="servo_shoulder_roll_r_Revolute_shoulder_roll_r"/>
        <position name="shoulder_pitch_r"          joint="shoulder_joint_r_Revolute_shoulder_pitch_r" />
        <position name="elbow_pitch_r"          joint="servo_elbow_pitch_r_Revolute_elbow_pitch_r" />
        <position name="wrist_pitch_r"          joint="servo_wrist_pitch_r_Revolute_wrist_pitch_r" />

        <!-- Left Arm -->
        <position name="shoulder_roll_l" joint="servo_shoulder_roll_l_Revolute_shoulder_roll_l"/>
        <position name="shoulder_pitch_l"          joint="shoulder_joint_l_Revolute_shoulder_pitch_l" />
        <position name="elbow_pitch_l"          joint="servo_elbow_pitch_l_Revolute_elbow_pitch_l" />
        <position name="wrist_pitch_l"          joint="servo_wrist_pitch_l_Revolute_wrist_pitch_l" />

        <!-- Right Leg -->
        <position name="hip_roll_r"   joint="servo_hip_roll_r_Revolute_hip_roll_r" />
        <position name="hip_pitch_r"  joint="hip_joint_r_Revolute_hip_pitch_r" />
        <position name="knee_pitch_r" joint="servo_knee_pitch_r_Revolute_knee_pitch_r" />
        <position name="ankle_pitch_r" joint="servo_ankle_pitch_r_Revolute_ankle_pitch_r" />

        <!-- Left Leg -->
        <position name="hip_roll_l"   joint="servo_hip_roll_l_Revolute_hip_roll_l" />
        <position name="hip_pitch_l"  joint="hip_joint_l_Revolute_hip_pitch_l" />
        <position name="knee_pitch_l" joint="servo_knee_pitch_l_Revolute_knee_pitch_l" />
        <position name="ankle_pitch_l" joint="servo_ankle_pitch_l_Revolute_ankle_pitch_l" />
    </actuator>

</mujoco>