<mujoco model="Robot_V3.2">
    
    <include file="wall.xml"/>
    <include file="groundplane.xml"/>
    <include file="route_ladder_V1.xml"/>

    <option gravity="0 0 0"/>
    <statistic center="0 0 0.2" extent="0.6"/>
    <compiler angle="radian" autolimits="true"/>

    <visual>
        <headlight diffuse="0.6 0.6 0.6" ambient="0.3 0.3 0.3" specular="0 0 0"/>
        <rgba haze="0.15 0.25 0.35 1"/>
        <global azimuth="160" elevation="-20"/>
    </visual>

    <default>
        <position kp="21.1" ctrlrange="-3.14 3.14" forcerange="-5 5"/>
        <joint damping="1.084" armature="0.045" frictionloss="0.03"/>
        <geom solref="0.004 1" conaffinity="0" contype="0" />
        <default class="collision_geom">
            <geom type="box" contype="1" conaffinity="1" solimp="0.99 0.99 0.01" solref="0.01 1" rgba="1 0 0 0.3"/>
        </default>
    </default>

    <asset>
        <mesh name="Chest" file="meshes/Chest.stl" scale="0.001 0.001 0.001" />
        <mesh name="servo_shoulder_yaw_r" file="meshes/servo_shoulder_yaw_r.stl" scale="0.001 0.001 0.001" />
        <mesh name="shoulder_link_r" file="meshes/shoulder_link_r.stl" scale="0.001 0.001 0.001" />
        <mesh name="servo_shoulder_yaw_l" file="meshes/servo_shoulder_yaw_l.stl" scale="0.001 0.001 0.001" />
        <mesh name="shoulder_link_l" file="meshes/shoulder_link_l.stl" scale="0.001 0.001 0.001" />
        <mesh name="servo_shoulder_pitch_l" file="meshes/servo_shoulder_pitch_l.stl" scale="0.001 0.001 0.001" />
        <mesh name="elbow_link_l" file="meshes/elbow_link_l.stl" scale="0.001 0.001 0.001" />
        <mesh name="servo_elbow_pitch_l" file="meshes/servo_elbow_pitch_l.stl" scale="0.001 0.001 0.001" />
        <mesh name="wrist_link_l" file="meshes/wrist_link_l.stl" scale="0.001 0.001 0.001" />
        <mesh name="servo_wrist_pitch_l" file="meshes/servo_wrist_pitch_l.stl" scale="0.001 0.001 0.001" />
        <mesh name="hand_l" file="meshes/hand_l.stl" scale="0.001 0.001 0.001" />
        <mesh name="servo_shoulder_pitch_r" file="meshes/servo_shoulder_pitch_r.stl" scale="0.001 0.001 0.001" />
        <mesh name="elbow_link_r" file="meshes/elbow_link_r.stl" scale="0.001 0.001 0.001" />
        <mesh name="servo_elbow_pitch_r" file="meshes/servo_elbow_pitch_r.stl" scale="0.001 0.001 0.001" />
        <mesh name="wrist_link_r" file="meshes/wrist_link_r.stl" scale="0.001 0.001 0.001" />
        <mesh name="servo_wrist_pitch_r" file="meshes/servo_wrist_pitch_r.stl" scale="0.001 0.001 0.001" />
        <mesh name="hand_r" file="meshes/hand_r.stl" scale="0.001 0.001 0.001" />
        <mesh name="servo_hip_yaw_l" file="meshes/servo_hip_yaw_l.stl" scale="0.001 0.001 0.001" />
        <mesh name="servo_hip_yaw_r" file="meshes/servo_hip_yaw_r.stl" scale="0.001 0.001 0.001" />
        <mesh name="hip_link_l" file="meshes/hip_link_l.stl" scale="0.001 0.001 0.001" />
        <mesh name="hip_link_r" file="meshes/hip_link_r.stl" scale="0.001 0.001 0.001" />
        <mesh name="servo_hip_pitch_l" file="meshes/servo_hip_pitch_l.stl" scale="0.001 0.001 0.001" />
        <mesh name="servo_knee_pitch_l" file="meshes/servo_knee_pitch_l.stl" scale="0.001 0.001 0.001" />
        <mesh name="knee_link_l" file="meshes/knee_link_l.stl" scale="0.001 0.001 0.001" />
        <mesh name="ankle_link_l" file="meshes/ankle_link_l.stl" scale="0.001 0.001 0.001" />
        <mesh name="servo_ankle_yaw_l" file="meshes/servo_ankle_yaw_l.stl" scale="0.001 0.001 0.001" />
        <mesh name="foot_l" file="meshes/foot_l.stl" scale="0.001 0.001 0.001" />
        <mesh name="servo_hip_pitch_r" file="meshes/servo_hip_pitch_r.stl" scale="0.001 0.001 0.001" />
        <mesh name="knee_link_r" file="meshes/knee_link_r.stl" scale="0.001 0.001 0.001" />
        <mesh name="servo_knee_pitch_r" file="meshes/servo_knee_pitch_r.stl" scale="0.001 0.001 0.001" />
        <mesh name="ankle_link_r" file="meshes/ankle_link_r.stl" scale="0.001 0.001 0.001" />
        <mesh name="servo_ankle_yaw_r" file="meshes/servo_ankle_yaw_r.stl" scale="0.001 0.001 0.001" />
        <mesh name="foot_r" file="meshes/foot_r.stl" scale="0.001 0.001 0.001" />
    </asset>
    <worldbody>
        <light directional="true" pos="-0.5 0.5 3" dir="0 0 -1" />

        <body name="chest" pos="0 0 0" euler="0 0 0">
            <freejoint/>
            <geom name="Chest_geom" type="mesh" mesh="Chest" pos="0 0 0" euler="0 0 0" />
            <inertial mass="0.7823774053524544" pos="-0.0002202141284941914 0.010665315313199322 -0.012037039216329091" fullinertia="0.0009304083466158194 0.0020382370707223204 0.0013134941144002763 -1.3551680123121551e-17 6.403442026300422e-17 4.9787921817003714e-05" />
            <body name="servo_shoulder_yaw_r" pos="-0.058620214128494295 0.020999999999999967 0.03302978684008116" euler="-0.0 -9.957992501029594e-17 -0.0">
                <geom name="servo_shoulder_yaw_r_geom" type="mesh" mesh="servo_shoulder_yaw_r" pos="0 0 0" euler="0 0 0" />
                <inertial mass="0.25164687718092266" pos="0.024182623706735695 -7.428014543364725e-07 -0.00970447868236431" fullinertia="4.382264110439028e-05 6.936512926283996e-05 4.143432391525749e-05 -1.6884100620981161e-09 1.9005141956557994e-06 -1.0197080945470779e-10" />
                <body name="shoulder_link_r" pos="0.0 4.440892098500626e-18 4.440892098500626e-18" euler="4.9303806576313227e-32 -3.3480526248275947e-16 1.1102230246251588e-16">
                    <joint name="servo_shoulder_yaw_r_Revolute_shoulder_yaw_r" type="hinge" axis="0.9999999999999994 -1.1102230246251583e-16 -4.3438518749305553e-16" pos="2.1412849429691667e-07 3.122507608081774e-17 2.1315991883402713e-07" />
                    <geom name="shoulder_link_r_geom" type="mesh" mesh="shoulder_link_r" pos="0 0 0" euler="0 0 0" />
                    <inertial mass="0.04536367978101093" pos="-0.013944636154283086 -0.005679169150879831 -0.00847954465007943" fullinertia="1.7057494663966787e-05 2.3284052485601595e-05 7.860019450784461e-06 -9.022824967105098e-07 -9.576858047656696e-07 -6.427073886900154e-07" />
                    <body name="servo_shoulder_pitch_r" pos="-0.020000000000000035 -0.02574999999999997 4.440892098500626e-18" euler="-8.151507262495669e-17 6.564297924180867e-16 -1.1102230246251554e-16">
                        <geom name="servo_shoulder_pitch_r_geom" type="mesh" mesh="servo_shoulder_pitch_r" pos="0 0 0" euler="0 0 0" />
                        <inertial mass="0.2971048465610437" pos="1.4564256804325284e-05 0.02720566999062764 -0.007552599078921751" fullinertia="9.514568280542259e-05 5.751940565774591e-05 6.179894487120087e-05 -6.674107594090917e-08 -4.9069307775127516e-08 -8.49196191019593e-06" />
                        <body name="elbow_link_r" pos="0.0 2.220446049250313e-18 0.0" euler="4.440892098500625e-16 0.0 -5.7740304523651276e-33">
                            <joint name="servo_shoulder_pitch_r_Revolute_shoulder_pitch_r" type="hinge" axis="3.12038244798698e-32 1.0 -3.6257413722510765e-16" pos="2.1412849432467235e-07 -4.3368009613146517e-17 2.1315991883402724e-07" />
                            <geom name="elbow_link_r_geom" type="mesh" mesh="elbow_link_r" pos="0 0 0" euler="0 0 0" />
                            <inertial mass="0.1558796574621319" pos="-0.03689020467118786 0.022976449621244656 -0.0031093557252406243" fullinertia="8.869603472439104e-05 0.00010676831454764198 0.0001448397099529904 -6.84573682427993e-06 -1.0505407646047525e-05 -2.2181380318676192e-06" />
                            <body name="servo_elbow_pitch_r" pos="-0.067 2.220446049250313e-18 4.440892098500626e-18" euler="-4.440892098500625e-16 0.0 -2.7369110631344083e-48">
                                <geom name="servo_elbow_pitch_r_geom" type="mesh" mesh="servo_elbow_pitch_r" pos="0 0 0" euler="0 0 0" />
                                <inertial mass="0.2971048465610437" pos="1.456425680430752e-05 0.02720566999062764 -0.007552599078921751" fullinertia="9.514568280542259e-05 5.751940565774504e-05 6.17989448711987e-05 -6.674107594112601e-08 -4.9069307775452776e-08 -8.49196191019593e-06" />
                                <body name="wrist_link_r" pos="0.0 2.220446049250313e-18 0.0" euler="4.440892098500625e-16 0.0 -0.0">
                                    <joint name="servo_elbow_pitch_r_Revolute_elbow_pitch_r" type="hinge" axis="3.12038244798698e-32 1.0 -3.6257413722510765e-16" pos="2.1412849432467235e-07 -4.770481830308854e-17 2.1315991881321056e-07" />
                                    <geom name="wrist_link_r_geom" type="mesh" mesh="wrist_link_r" pos="0 0 0" euler="0 0 0" />
                                    <inertial mass="0.1558796574621319" pos="-0.03689020467118787 0.02297644962124465 -0.0031093557252406243" fullinertia="8.869603472439104e-05 0.00010676831454764241 0.00014483970995299127 -6.845736824279876e-06 -1.0505407646047525e-05 -2.2181380318676328e-06" />
                                    <body name="servo_wrist_pitch_r" pos="-0.06699999999999999 2.220446049250313e-18 -4.440892098500626e-18" euler="-4.440892098500625e-16 0.0 -2.7369110631344083e-48">
                                        <geom name="servo_wrist_pitch_r_geom" type="mesh" mesh="servo_wrist_pitch_r" pos="0 0 0" euler="0 0 0" />
                                        <inertial mass="0.2971048465610437" pos="1.4564256804343046e-05 0.02720566999062764 -0.007552599078921751" fullinertia="9.514568280542265e-05 5.751940565774591e-05 6.179894487120217e-05 -6.674107594080075e-08 -4.9069307775019096e-08 -8.491961910195902e-06" />
                                        <body name="hand_r" pos="0.0 2.220446049250313e-18 0.0" euler="2.465190328815671e-32 -9.860761315262684e-31 4.9303806576313e-32">
                                            <joint name="servo_wrist_pitch_r_Revolute_wrist_pitch_r" type="hinge" axis="2.2991789269902714e-30 0.9999999999999962 8.151507262495454e-17" pos="2.1412849432467235e-07 -5.204172165505028e-17 2.1315991880627087e-07" />
                                            <geom name="hand_r_geom" type="mesh" mesh="hand_r" pos="0 0 0" euler="0 0 0" />
                                            <geom name="hand_r_collision1" class="collision_geom" pos="0 -0.0018 0.03" size="0.01 0.0015 0.043" />
                                            <geom name="hand_r_collision2" class="collision_geom" pos="0 -0.011 0.075" size="0.01 0.009 0.0015" />
                                            <geom name="hand_r_collision3" class="collision_geom" pos="0 -0.021 0.07" size="0.01 0.0015 0.005" />
                                            <inertial mass="0.01773152480757101" pos="1.0117117303526175e-14 0.016822628119887734 0.03655428177592157" fullinertia="2.303232142869756e-05 1.1536574784605273e-05 1.2648677821680177e-05 -7.089019484494938e-18 6.561728775579679e-18 4.718790043704822e-06" />
                                            <!-- Reference for forward kinematics. Thats the reference point for hand_r of the robot -->
                                            <body name="hand_r_ref" pos="0 -0.011 0.073" euler="0 0 0">
                                                <geom type="sphere" size="0.005" rgba="0 0 1 1"/>
                                            </body>
                                        </body>
                                    </body>
                                </body>
                            </body>
                        </body>
                    </body>
                </body>
            </body>
            <body name="servo_shoulder_yaw_l" pos="0.05817978587150584 0.020999999999999987 0.03302978684008128" euler="-0.0 4.555315873022871e-16 -1.5648180798146291e-34">
                <geom name="servo_shoulder_yaw_l_geom" type="mesh" mesh="servo_shoulder_yaw_l" pos="0 0 0" euler="0 0 0" />
                <inertial mass="0.2516468771809226" pos="-0.02418262370673598 7.428014543542404e-07 -0.009704478682364332" fullinertia="4.3822641104279705e-05 6.93651292627285e-05 4.143432391525543e-05 -1.6884100620981314e-09 -1.9005141956553977e-06 1.019708094818053e-10" />
                <body name="shoulder_link_l" pos="0.0 -8.881784197001253e-18 0.0" euler="-4.930380657631311e-31 -3.701891023484629e-15 -2.664535259100386e-15">
                    <joint name="servo_shoulder_yaw_l_Revolute_shoulder_yaw_l" type="hinge" axis="0.9999999999999991 2.6645352591003836e-15 -3.24635943618236e-15" pos="2.141284941650778e-07 2.081717127536684e-17 2.1315991871606511e-07" />
                    <geom name="shoulder_link_l_geom" type="mesh" mesh="shoulder_link_l" pos="0 0 0" euler="0 0 0" />
                    <inertial mass="0.045363679781011024" pos="0.013944636154283116 -0.005679169150879887 -0.008479544650079445" fullinertia="1.7057494663966787e-05 2.3284052485602645e-05 7.860019450784492e-06 9.022824967106163e-07 9.576858047655555e-07 -6.427073886900533e-07" />
                    <body name="servo_shoulder_pitch_l" pos="0.020000000000000018 -0.025749999999999905 8.881784197001253e-18" euler="-6.632230350018044e-16 2.5802256214072676e-15 2.6645352591003635e-15">
                        <geom name="servo_shoulder_pitch_l_geom" type="mesh" mesh="servo_shoulder_pitch_l" pos="0 0 0" euler="0 0 0" />
                        <inertial mass="0.2971048465610437" pos="1.4564256804327455e-05 0.027205669990627637 -0.007552599078921749" fullinertia="9.514568280542254e-05 5.7519405657746356e-05 6.179894487120087e-05 -6.674107594102509e-08 -4.906930777515717e-08 -8.491961910195958e-06" />
                        <body name="elbow_link_l" pos="0.0 2.220446049250313e-18 0.0" euler="-9.860761315262648e-32 0.0 -1.0054658198697066e-31">
                            <joint name="servo_shoulder_pitch_l_Revolute_shoulder_pitch_l" type="hinge" axis="-2.9388387062353524e-31 -1.0 -6.63223035001816e-16" pos="2.1412849422752802e-07 7.892977678437651e-17 2.1315991868831028e-07" />
                            <geom name="elbow_link_l_geom" type="mesh" mesh="elbow_link_l" pos="0 0 0" euler="0 0 0" />
                            <inertial mass="0.15587965737437795" pos="0.03689020466718535 0.022976449632940984 -0.0031093557084483966" fullinertia="8.869603460563667e-05 0.00010676831446345281 0.00014483970990954685 6.845736811317306e-06 1.050540762743842e-05 -2.21813797748446e-06" />
                            <body name="servo_elbow_pitch_l" pos="0.06700000000000003 2.220446049250313e-18 -8.881784197001253e-18" euler="-0.0 0.0 1.4791141972893967e-31">
                                <geom name="servo_elbow_pitch_l_geom" type="mesh" mesh="servo_elbow_pitch_l" pos="0 0 0" euler="0 0 0" />
                                <inertial mass="0.2971048465610437" pos="1.4564256804336337e-05 0.027205669990627637 -0.007552599078921749" fullinertia="9.514568280542254e-05 5.751940565774592e-05 6.179894487120044e-05 -6.674107594069983e-08 -4.906930777504875e-08 -8.491961910195931e-06" />
                                <body name="wrist_link_l" pos="0.0 2.220446049250313e-18 0.0" euler="-0.0 0.0 -1.4791141972893954e-31">
                                    <joint name="servo_elbow_pitch_l_Revolute_elbow_pitch_l" type="hinge" axis="-2.938838706235354e-31 -1.0 -6.63223035001816e-16" pos="2.1412849421365023e-07 7.459296809443452e-17 2.131599186536158e-07" />
                                    <geom name="wrist_link_l_geom" type="mesh" mesh="wrist_link_l" pos="0 0 0" euler="0 0 0" />
                                    <inertial mass="0.15587965737437795" pos="0.03689020466718535 0.022976449632940984 -0.0031093557084483966" fullinertia="8.869603460563667e-05 0.00010676831446345455 0.00014483970990954772 6.845736811317252e-06 1.050540762743842e-05 -2.21813797748446e-06" />
                                    <body name="servo_wrist_pitch_l" pos="0.06700000000000002 2.220446049250313e-18 -1.3322676295501878e-17" euler="-0.0 0.0 -0.0">
                                        <geom name="servo_wrist_pitch_l_geom" type="mesh" mesh="servo_wrist_pitch_l" pos="0 0 0" euler="0 0 0" />
                                        <inertial mass="0.2971048465610437" pos="1.4564256804336337e-05 0.027205669990627637 -0.007552599078921749" fullinertia="9.514568280542265e-05 5.751940565774419e-05 6.179894487120217e-05 -6.674107594080825e-08 -4.906930777504875e-08 -8.491961910195931e-06" />
                                        <body name="hand_l" pos="0.0 2.220446049250313e-18 0.0" euler="-0.0 0.0 8.758115402030107e-47">
                                            <joint name="servo_wrist_pitch_l_Revolute_wrist_pitch_l" type="hinge" axis="-2.938838706235354e-31 -0.9999999999999991 -6.632230350018154e-16" pos="2.1412849421365023e-07 7.025615940449246e-17 2.1315991861892116e-07" />
                                            <geom name="hand_l_geom" type="mesh" mesh="hand_l" pos="0 0 0" euler="0 0 0" />
                                            <geom name="hand_l_collision1" class="collision_geom" pos="0 -0.0018 0.03" size="0.01 0.0015 0.043" />
                                            <geom name="hand_l_collision2" class="collision_geom" pos="0 -0.011 0.075" size="0.01 0.009 0.0015" />
                                            <geom name="hand_l_collision3" class="collision_geom" pos="0 -0.021 0.07" size="0.01 0.0015 0.005" />
                                            <inertial mass="0.01773152480757101" pos="1.0114056890959181e-14 0.016822628119887835 0.03655428177592178" fullinertia="2.3032321428697385e-05 1.1536574784605334e-05 1.2648677821680147e-05 -7.084828357011048e-18 6.6067163560343586e-18 4.718790043704877e-06" />
                                            <!-- Reference for forward kinematics. Thats the reference point for hand_l of the robot -->
                                            <body name="hand_l_ref" pos="0 -0.011 0.073" euler="0 0 0">
                                                <geom type="sphere" size="0.005" rgba="0 0 1 1"/>
                                            </body>
                                        </body>
                                    </body>
                                </body>
                            </body>
                        </body>
                    </body>
                </body>
            </body>
            <body name="servo_hip_yaw_l" pos="0.04302978587150579 0.02099999999999999 -0.07162021412849424" euler="2.2204460492503126e-16 -4.3790577010150495e-47 -0.0">
                <geom name="servo_hip_yaw_l_geom" type="mesh" mesh="servo_hip_yaw_l" pos="0 0 0" euler="0 0 0" />
                <inertial mass="0.25164687718092266" pos="-0.009704478682364305 7.42801454346283e-07 0.024182623706735712" fullinertia="4.143432391525738e-05 6.936512926272861e-05 4.3822641104278824e-05 1.0197080940091986e-10 1.9005141956557727e-06 1.6884100623634951e-09" />
                <body name="hip_link_l" pos="0.0 -4.440892098500626e-18 0.0" euler="-2.2204460492503067e-16 -9.860761315262617e-32 6.077163357286268e-62">
                    <joint name="servo_hip_yaw_l_Revolute_hip_yaw_l" type="hinge" axis="-1.4791141972893925e-31 -5.91645678915759e-31 -1.0" pos="2.141284942067112e-07 1.3877787807814457e-17 2.1412849424140568e-07" />
                    <geom name="hip_link_l_geom" type="mesh" mesh="hip_link_l" pos="0 0 0" euler="0 0 0" />
                    <inertial mass="0.04536367978101078" pos="0.005679169150879932 0.008479544650079501 -0.013944636154283083" fullinertia="2.3284052485714115e-05 7.860019450883445e-06 1.705749466398036e-05 -6.427073886900489e-07 9.022824967103225e-07 9.57685804765622e-07" />
                    <body name="servo_hip_pitch_l" pos="0.025750000000000002 4.440892098500626e-18 -0.01999999999999999" euler="-9.860761315262648e-32 -4.440892098500625e-16 -4.132471082954665e-62">
                        <geom name="servo_hip_pitch_l_geom" type="mesh" mesh="servo_hip_pitch_l" pos="0 0 0" euler="0 0 0" />
                        <inertial mass="0.2971048465610437" pos="-0.027205669990627623 0.0075525990789217755 1.4564256804335689e-05" fullinertia="5.751940565774591e-05 6.179894487120131e-05 9.514568280542238e-05 -8.49196191019593e-06 6.674107594710772e-08 4.9069307775030266e-08" />
                        <body name="knee_link_l" pos="0.0 0.0 0.0" euler="-0.0 -9.860761315262648e-32 -0.0">
                            <joint name="servo_hip_pitch_l_Revolute_hip_pitch_l" type="hinge" axis="-1.0 0.0 -4.440892098500627e-16" pos="2.1412849419977242e-07 1.0408340855860843e-17 2.1412849424140557e-07" />
                            <geom name="knee_link_l_geom" type="mesh" mesh="knee_link_l" pos="0 0 0" euler="0 0 0" />
                            <inertial mass="0.15587965599967016" pos="-0.022976449595223283 0.003109355487147418 -0.03689020461080877" fullinertia="0.00010676831355273817 0.00014483970948604274 8.86960333110208e-05 -2.218138134804871e-06 6.84573685036989e-06 1.0505407406902062e-05" />
                            <body name="servo_knee_pitch_l" pos="2.6645352591003756e-17 -4.440892098500626e-18 -0.06700000000000003" euler="-0.0 9.860761315262648e-32 -0.0">
                                <geom name="servo_knee_pitch_l_geom" type="mesh" mesh="servo_knee_pitch_l" pos="0 0 0" euler="0 0 0" />
                                <inertial mass="0.2971048465610437" pos="-0.027205669990627623 0.0075525990789217755 1.4564256804335689e-05" fullinertia="5.7519405657746776e-05 6.179894487120217e-05 9.514568280542238e-05 -8.491961910195875e-06 6.67410759475414e-08 4.9069307775463947e-08" />
                                <body name="ankle_link_l" pos="0.0 0.0 0.0" euler="4.930380657631324e-32 -2.220446049250312e-16 -2.1895288505075228e-47">
                                    <joint name="servo_knee_pitch_l_Revolute_knee_pitch_l" type="hinge" axis="1.0 0.0 -6.661338147750938e-16" pos="2.141284941442613e-07 1.3877787807814457e-17 2.1412849424140554e-07" />
                                    <geom name="ankle_link_l_geom" type="mesh" mesh="ankle_link_l" pos="0 0 0" euler="0 0 0" />
                                    <inertial mass="0.013004386860980391" pos="-0.02541625102934873 -1.7781331962396507e-14 -0.025777329897467158" fullinertia="5.276273904760277e-06 1.2786255215625959e-05 8.369185492904545e-06 -5.554842068093699e-18 -1.1187878600831545e-07 3.625301014248409e-18" />
                                    <body name="servo_ankle_yaw_l" pos="-0.025750000000000002 8.881784197001253e-18 -0.047000000000000014" euler="1.7256332301709633e-31 6.661338147750937e-16 8.157786440681343e-32">
                                        <joint name="ankle_link_l_Revolute_ankle_yaw_l" type="hinge" axis="0.0 -7.1490519535654195e-31 -1.0" pos="2.1412849412344448e-07 3.469446951953614e-18 2.1412849429691683e-07" />
                                        <geom name="servo_ankle_yaw_l_geom" type="mesh" mesh="servo_ankle_yaw_l" pos="0 0 0" euler="0 0 0" />
                                        <inertial mass="0.2516468771809227" pos="7.42801454354236e-07 -0.009704478682364305 -0.024182623706735705" fullinertia="6.936512926272904e-05 4.143432391525738e-05 4.3822641104278716e-05 1.0197080945470796e-10 -1.6884100623691667e-09 -1.900514195655881e-06" />
                                        <body name="foot_l" pos="-2.1234156655225434e-10 -0.015374999769031988 -0.04639999999999997" euler="-3.254051234036674e-30 9.860761315262648e-32 1.2518956516009719e-61">
                                            <geom name="foot_l_geom" type="mesh" mesh="foot_l" pos="0 0 0" euler="0 0 0" />
                                            <geom name="foot_l_collision1" class="collision_geom" pos="0 0 -0.002" size="0.025 0.036 0.002" />
                                            <geom name="foot_l_collision2" class="collision_geom" pos="0.023 -0.034 -0.008" size="0.002 0.002 0.004" />
                                            <geom name="foot_l_collision3" class="collision_geom" pos="-0.023 -0.034 -0.008" size="0.002 0.002 0.004" />
                                            <inertial mass="0.17769608247486798" pos="-2.5936852665608967e-12 0.0012680683941235582 0.005998981687306575" fullinertia="0.00012098642848960145 5.57192217540952e-05 0.00012330401556899165 -3.5532083460416974e-15 -9.82284999867522e-14 -5.751272659478728e-06" />
                                            <!-- Reference for forward kinematics. Thats the reference point for foot_l of the robot -->
                                            <body name="foot_l_ref" pos="-0.018 -0.029 -0.004" euler="0 0 0">
                                                <geom type="sphere" size="0.005" rgba="0 0 1 1"/>
                                            </body>
                                        </body>
                                    </body>
                                </body>
                            </body>
                        </body>
                    </body>
                </body>
            </body>
            <body name="servo_hip_yaw_r" pos="-0.04347021412849422 0.021 -0.07162021412849429" euler="2.2204460492503126e-16 -4.3790577010150495e-47 -0.0">
                <geom name="servo_hip_yaw_r_geom" type="mesh" mesh="servo_hip_yaw_r" pos="0 0 0" euler="0 0 0" />
                <inertial mass="0.2516468771809227" pos="0.009704478682364305 -7.428014543399846e-07 0.024182623706735695" fullinertia="4.143432391525749e-05 6.936512926283952e-05 4.3822641104389955e-05 1.0197080948139101e-10 -1.900514195655881e-06 -1.6884100621037877e-09" />
                <body name="hip_link_r" pos="0.0 -4.440892098500626e-18 0.0" euler="-4.930380657631324e-32 5.964789062427953e-47 2.1590421387736112e-78">
                    <joint name="servo_hip_yaw_r_Revolute_hip_yaw_r" type="hinge" axis="0.0 2.220446049250312e-16 1.0" pos="2.14128494220589e-07 3.4694944980305305e-18 2.1412849428303904e-07" />
                    <geom name="hip_link_r_geom" type="mesh" mesh="hip_link_r" pos="0 0 0" euler="0 0 0" />
                    <inertial mass="0.04536367978101114" pos="-0.005679169150879871 0.008479544650079435 -0.013944636154283147" fullinertia="2.3284052485601683e-05 7.860019450784404e-06 1.705749466396689e-05 6.427073886900351e-07 -9.022824967103497e-07 9.576858047656783e-07" />
                    <body name="servo_hip_pitch_r" pos="-0.025749999999999985 8.881784197001253e-18 -0.019999999999999938" euler="-0.0 -4.930380657631325e-32 -0.0">
                        <geom name="servo_hip_pitch_r_geom" type="mesh" mesh="servo_hip_pitch_r" pos="0 0 0" euler="0 0 0" />
                        <inertial mass="0.2971048465610435" pos="0.027205669990627623 0.007552599078921785 -1.4564256804325284e-05" fullinertia="5.7519405657908106e-05 6.179894487120087e-05 9.51456828055837e-05 8.491961910196417e-06 6.674107594101759e-08 -4.906930777512751e-08" />
                        <body name="knee_link_r" pos="0.0 0.0 0.0" euler="2.465190328815662e-32 -2.220446049250312e-16 -2.498001805406602e-16">
                            <joint name="servo_hip_pitch_r_Revolute_hip_pitch_r" type="hinge" axis="-1.0 2.498001805406602e-16 -2.2204460492503126e-16" pos="2.1412849419977237e-07 -1.0408239820447425e-17 2.1412849424140562e-07" />
                            <geom name="knee_link_r_geom" type="mesh" mesh="knee_link_r" pos="0 0 0" euler="0 0 0" />
                            <inertial mass="0.15587965737437867" pos="0.022976449632940873 0.0031093557084483888 -0.03689020466718539" fullinertia="0.00010676831446345628 0.00014483970990954945 8.869603460563789e-05 2.2181379774839065e-06 -6.84573681131781e-06 1.0505407627437713e-05" />
                            <body name="servo_knee_pitch_r" pos="0.0 8.881784197001253e-18 -0.06699999999999999" euler="-2.465190328815662e-32 2.220446049250312e-16 2.498001805406602e-16">
                                <geom name="servo_knee_pitch_r_geom" type="mesh" mesh="servo_knee_pitch_r" pos="0 0 0" euler="0 0 0" />
                                <inertial mass="0.2971048465610435" pos="0.027205669990627623 0.007552599078921789 -1.456425680430752e-05" fullinertia="5.751940565790984e-05 6.179894487120217e-05 9.514568280558381e-05 8.491961910196471e-06 6.674107594058391e-08 -4.906930777523593e-08" />
                                <body name="ankle_link_r" pos="0.0 0.0 0.0" euler="-0.0 -2.2204460492503126e-16 1.2880252548782238e-47">
                                    <joint name="servo_knee_pitch_r_Revolute_knee_pitch_r" type="hinge" axis="1.0 -1.2880252548782235e-47 -2.220446049250313e-16" pos="2.1412849418589458e-07 -3.1224975021505627e-17 2.1412849421365005e-07" />
                                    <geom name="ankle_link_r_geom" type="mesh" mesh="ankle_link_r" pos="0 0 0" euler="0 0 0" />
                                    <inertial mass="0.01300438686098039" pos="0.025416251029348712 1.7775608245363402e-14 -0.025777329897467147" fullinertia="5.276273904753284e-06 1.2786255215616851e-05 8.369185492902465e-06 -5.5497350283293376e-18 1.1187878600831818e-07 -3.612729273593841e-18" />
                                    <body name="servo_ankle_yaw_r" pos="0.025749999999999985 -4.440892098500626e-18 -0.047000000000000014" euler="-1.2246467991473532e-16 2.220446049250313e-16 -5.473822126268817e-48">
                                        <joint name="ankle_link_r_Revolute_ankle_yaw_r" type="hinge" axis="0.0 9.957992501029594e-17 1.0" pos="2.1412849419283342e-07 -3.4694448196636745e-17 2.141284942136501e-07" />
                                        <geom name="servo_ankle_yaw_r_geom" type="mesh" mesh="servo_ankle_yaw_r" pos="0 0 0" euler="0 0 0" />
                                        <inertial mass="0.2516468771809227" pos="7.42801454354236e-07 -0.009704478682364306 -0.024182623706735705" fullinertia="6.936512926273078e-05 4.143432391525738e-05 4.3822641104278716e-05 1.0197080945470779e-10 -1.6884100619354858e-09 -1.9005141956557723e-06" />
                                        <body name="foot_r" pos="-2.1234154878868596e-10 -0.015374999769031965 -0.04639999999999997" euler="-3.254051234036674e-30 9.860761315262648e-32 1.0947644252537633e-47">
                                            <geom name="foot_r_geom" type="mesh" mesh="foot_r" pos="0 0 0" euler="0 0 0" />
                                            <geom name="foot_r_collision1" class="collision_geom" pos="0 0 -0.002" size="0.025 0.036 0.002" />
                                            <geom name="foot_r_collision2" class="collision_geom" pos="0.023 -0.034 -0.008" size="0.002 0.002 0.004" />
                                            <geom name="foot_r_collision3" class="collision_geom" pos="-0.023 -0.034 -0.008" size="0.002 0.002 0.004" />
                                            <inertial mass="0.17769608247486798" pos="-2.5936852665608967e-12 0.001268068394123559 0.005998981687306575" fullinertia="0.00012098642848960145 5.571922175409694e-05 0.0001233040155689916 -3.553215122305285e-15 -9.82284999867522e-14 -5.751272659478722e-06" />
                                            <!-- Reference for forward kinematics. Thats the reference point for foot_r of the robot -->
                                            <body name="foot_r_ref" pos="0.018 -0.029 -0.004" euler="0 0 0">
                                                <geom type="sphere" size="0.005" rgba="0 0 1 1"/>
                                            </body>
                                        </body>
                                    </body>
                                </body>
                            </body>
                        </body>
                    </body>
                </body>
            </body>
        </body>
        <body name="target_marker" pos="0 0.0 0" mocap="true" euler="0 0 0">
            <geom type="sphere" size="0.01" rgba="1 0 1 1"/>
        </body>
    </worldbody>

    <actuator>
        <!-- Right Arm -->
        <position name="shoulder_yaw_r"        joint="servo_shoulder_yaw_r_Revolute_shoulder_yaw_r"/>
        <position name="shoulder_pitch_r"       joint="servo_shoulder_pitch_r_Revolute_shoulder_pitch_r" />
        <position name="elbow_pitch_r"          joint="servo_elbow_pitch_r_Revolute_elbow_pitch_r" />
        <position name="wrist_pitch_r"          joint="servo_wrist_pitch_r_Revolute_wrist_pitch_r" />

        <!-- Left Arm -->
        <position name="shoulder_yaw_l" joint="servo_shoulder_yaw_l_Revolute_shoulder_yaw_l"/>
        <position name="shoulder_pitch_l"          joint="servo_shoulder_pitch_l_Revolute_shoulder_pitch_l" />
        <position name="elbow_pitch_l"          joint="servo_elbow_pitch_l_Revolute_elbow_pitch_l" />
        <position name="wrist_pitch_l"          joint="servo_wrist_pitch_l_Revolute_wrist_pitch_l" />

        <!-- Right Leg -->
        <position name="hip_yaw_r"   joint="servo_hip_yaw_r_Revolute_hip_yaw_r" />
        <position name="hip_pitch_r"  joint="servo_hip_pitch_r_Revolute_hip_pitch_r" />
        <position name="knee_pitch_r" joint="servo_knee_pitch_r_Revolute_knee_pitch_r" />
        <position name="ankle_yaw_r" joint="ankle_link_r_Revolute_ankle_yaw_r" />

        <!-- Left Leg -->
        <position name="hip_yaw_l"   joint="servo_hip_yaw_l_Revolute_hip_yaw_l" />
        <position name="hip_pitch_l"  joint="servo_hip_pitch_l_Revolute_hip_pitch_l" />
        <position name="knee_pitch_l" joint="servo_knee_pitch_l_Revolute_knee_pitch_l"  />
        <position name="ankle_yaw_l" joint="ankle_link_l_Revolute_ankle_yaw_l" />
    </actuator>

</mujoco>