<mujoco model="Robot_V3">
    
    <include file="wall.xml"/>
    <include file="groundplane.xml"/>
    <include file="route_ladder_V1.xml"/>

    <option gravity="0 0 -9.81"/>
    <statistic center="0 0 0.2" extent="0.6"/>
    <compiler angle="radian" autolimits="true"/>

    <visual>
        <headlight diffuse="0.6 0.6 0.6" ambient="0.3 0.3 0.3" specular="0 0 0"/>
        <rgba haze="0.15 0.25 0.35 1"/>
        <global azimuth="160" elevation="-20"/>
    </visual>

    <default>
        <position kp="21.1" ctrlrange="-1.5708 1.5708" forcerange="-5 5"/>
        <joint damping="1.084" armature="0.045" frictionloss="0.03"/>
        <geom solref="0.004 1" conaffinity="0" contype="0" />
        <default class="collision_geom">
            <geom type="box" contype="1" conaffinity="1" solimp="0.99 0.99 0.01" solref="0.01 1" rgba="1 0 0 0.3"/>
        </default>
    </default>

    <asset>
        <mesh name="servo_shoulder_roll_r" file="meshes/servo_shoulder_roll_r.stl" scale="0.001 0.001 0.001" />
        <mesh name="servo_shoulder_roll_l" file="meshes/servo_shoulder_roll_l.stl" scale="0.001 0.001 0.001" />
        <mesh name="servo_hip_roll_l" file="meshes/servo_hip_roll_l.stl" scale="0.001 0.001 0.001" />
        <mesh name="servo_hip_roll_r" file="meshes/servo_hip_roll_r.stl" scale="0.001 0.001 0.001" />
        <mesh name="servo_hip_pitch_r" file="meshes/servo_hip_pitch_r.stl" scale="0.001 0.001 0.001" />
        <mesh name="servo_hip_pitch_l" file="meshes/servo_hip_pitch_l.stl" scale="0.001 0.001 0.001" />
        <mesh name="knee_joint_r" file="meshes/knee_joint_r.stl" scale="0.001 0.001 0.001" />
        <mesh name="knee_joint_l" file="meshes/knee_joint_l.stl" scale="0.001 0.001 0.001" />
        <mesh name="servo_knee_pitch_r" file="meshes/servo_knee_pitch_r.stl" scale="0.001 0.001 0.001" />
        <mesh name="servo_knee_pitch_l" file="meshes/servo_knee_pitch_l.stl" scale="0.001 0.001 0.001" />
        <mesh name="servo_ankle_pitch_r" file="meshes/servo_ankle_pitch_r.stl" scale="0.001 0.001 0.001" />
        <mesh name="servo_ankle_pitch_l" file="meshes/servo_ankle_pitch_l.stl" scale="0.001 0.001 0.001" />
        <mesh name="servo_shoulder_pitch_r" file="meshes/servo_shoulder_pitch_r.stl" scale="0.001 0.001 0.001" />
        <mesh name="elbow_joint_r" file="meshes/elbow_joint_r.stl" scale="0.001 0.001 0.001" />
        <mesh name="servo_elbow_pitch_r" file="meshes/servo_elbow_pitch_r.stl" scale="0.001 0.001 0.001" />
        <mesh name="servo_wrist_pitch_r" file="meshes/servo_wrist_pitch_r.stl" scale="0.001 0.001 0.001" />
        <mesh name="ankle_joint_l" file="meshes/ankle_joint_l.stl" scale="0.001 0.001 0.001" />
        <mesh name="ankle_joint_r" file="meshes/ankle_joint_r.stl" scale="0.001 0.001 0.001" />
        <mesh name="wrist_joint_r" file="meshes/wrist_joint_r.stl" scale="0.001 0.001 0.001" />
        <mesh name="shoulder_joint_l" file="meshes/shoulder_joint_l.stl" scale="0.001 0.001 0.001" />
        <mesh name="hip_joint_l" file="meshes/hip_joint_l.stl" scale="0.001 0.001 0.001" />
        <mesh name="hip_joint_r" file="meshes/hip_joint_r.stl" scale="0.001 0.001 0.001" />
        <mesh name="servo_shoulder_pitch_l" file="meshes/servo_shoulder_pitch_l.stl" scale="0.001 0.001 0.001" />
        <mesh name="elbow_joint_l" file="meshes/elbow_joint_l.stl" scale="0.001 0.001 0.001" />
        <mesh name="servo_elbow_pitch_l" file="meshes/servo_elbow_pitch_l.stl" scale="0.001 0.001 0.001" />
        <mesh name="wrist_joint_l" file="meshes/wrist_joint_l.stl" scale="0.001 0.001 0.001" />
        <mesh name="servo_wrist_pitch_l" file="meshes/servo_wrist_pitch_l.stl" scale="0.001 0.001 0.001" />
        <mesh name="shoulder_joint_r" file="meshes/shoulder_joint_r.stl" scale="0.001 0.001 0.001" />
        <mesh name="hand_r" file="meshes/hand_r.stl" scale="0.001 0.001 0.001" />
        <mesh name="hand_l" file="meshes/hand_l.stl" scale="0.001 0.001 0.001" />
        <mesh name="foot_l" file="meshes/foot_l.stl" scale="0.001 0.001 0.001" />
        <mesh name="foot_r" file="meshes/foot_r.stl" scale="0.001 0.001 0.001" />
        <mesh name="Chest" file="meshes/Chest.stl" scale="0.001 0.001 0.001" />
    </asset>

    <worldbody>
        <light directional="true" pos="-0.5 0.5 3" dir="0 0 -1" />

        <body name="chest" pos="0 -0.11 0.32" euler="1.5708 0 0">
            <freejoint/>
            <geom name="Chest_geom" type="mesh" mesh="Chest" pos="0 0 0" euler="0 0 0" />
            <inertial mass="0.7415574053524537" pos="-3.433299584696394e-15 0.08445932318212247 -0.0645118952816469" fullinertia="0.0008914936276538377 0.001124446779639699 0.0018221335867671636 2.0942071596588286e-17 9.525762499184918e-18 4.657367742361267e-05" />
            <body name="servo_shoulder_roll_l" pos="0.06710384800005438 0.10224999417966729 -0.10154565551562772" euler="6.123233995736744e-17 9.714451465468992e-16 1.5707963267948966">
                <geom name="servo_shoulder_roll_l_geom" type="mesh" mesh="servo_shoulder_roll_l" pos="0 0 0" euler="0 0 0" />
                <inertial mass="0.25164687718092266" pos="0.016295528106545602 0.03288647170679027 0.04754491271418394" fullinertia="4.1434323908684186e-05 4.3822641116561845e-05 6.936512928157397e-05 1.9005141956643472e-06 -1.0197049271450262e-10 -1.6884099909692926e-09" />
                <body name="shoulder_joint_l" pos="0.026000006788908722 -0.012546145327643981 0.11529565334782302" euler="-2.3592239273284833e-16 1.5707963267948966 0">
                    <joint name="servo_shoulder_roll_l_Revolute_shoulder_roll_l" type="hinge" axis="-1.1657341758565303e-15 1.000000000000001 -6.591949208634243e-17" pos="0.06775032196015857 0.021250317455660854 -9.685760441415776e-10" />
                    <geom name="shoulder_joint_l_geom" type="mesh" mesh="shoulder_joint_l" pos="0 0 0" euler="0 0 0" />
                    <inertial mass="0.013004386860980393" pos="0.0680837468028471 2.732322516576015e-05 -1.782462061897211e-14" fullinertia="5.276273904760452e-06 8.369185492904732e-06 1.2786255215626101e-05 1.118787860083277e-07 -5.535543744056867e-18 -3.685979776607171e-18" />
                    <body name="servo_shoulder_pitch_l" pos="0.10220384583225074 0.021795648843326118 -0.026000006788908295" euler="1.5707963267948963 -1.7319479184152376e-14 1.5707963267948966">
                        <joint name="shoulder_joint_l_Revolute_shoulder_pitch_l" type="hinge" axis="1.4693447715984025e-16 -1.0000000000000024 -1.8485213360008967e-14" pos="0.026000005820332277 0.008703523872091496 0.04754533138766554" />
                        <geom name="servo_shoulder_pitch_l_geom" type="mesh" mesh="servo_shoulder_pitch_l" pos="0 0 0" euler="0 0 0" />
                        <inertial mass="0.2574774645033229" pos="0.016612363704313418 0.03333463847036317 0.04754288849972729" fullinertia="4.435486308624488e-05 4.572278841338145e-05 7.311602559771348e-05 3.6130695128474585e-07 7.0274044882047996e-09 8.375458181896025e-09" />
                        <body name="elbow_joint_l" pos="-0.014499993211091428 0.030103848000053494 0.10354565551562742" euler="-3.1415926535897762 -5.689893001204057e-16 -1.8041124150159607e-16">
                            <geom name="elbow_joint_l_geom" type="mesh" mesh="elbow_joint_l" pos="0 0 0" euler="0 0 0" />
                            <inertial mass="0.0940156941457831" pos="0.030249999999995513 0.0025000000000000118 0.03600000000000004" fullinertia="3.813578891955764e-05 7.543913942453982e-05 3.767401128966509e-05 2.5890916049164776e-20 8.366962357176884e-19 5.037712188645445e-20" />
                            <body name="servo_elbow_pitch_l" pos="0.014499993211091642 0.03010384800005416 0.06354565551562728" euler="-3.141592653589792 -7.216449660063577e-16 -2.2204460492502874e-16">
                                <geom name="servo_elbow_pitch_l_geom" type="mesh" mesh="servo_elbow_pitch_l" pos="0 0 0" euler="0 0 0" />
                                <inertial mass="0.2574774645033229" pos="0.016612363704313324 0.03333463847036301 0.04754288849972698" fullinertia="4.4354863086244756e-05 4.572278841338123e-05 7.311602559771305e-05 3.613069512849671e-07 7.027404491660753e-09 8.375458181968741e-09" />
                                <body name="wrist_joint_l" pos="-0.014499993211092068 0.11970384512458716 0.09254565574378958" euler="-3.1415926535897913 -7.75455381207649e-17 -1.5707963267948966">
                                    <joint name="servo_elbow_pitch_l_Revolute_elbow_pitch_l" type="hinge" axis="1.0000000000000016 4.081770351527427e-16 1.7208456881688769e-15" pos="-0.11100032125249623 0.04049999903142404 0.045000324356124215" />
                                    <geom name="wrist_joint_l_geom" type="mesh" mesh="wrist_joint_l" pos="0 0 0" euler="0 0 0" />
                                    <inertial mass="0.2138444469189371" pos="-0.08668705192306546 0.03338795334782354 0.005881885304377473" fullinertia="0.0001395631746126326 0.00016881014969251026 0.0001395167696510612 -6.21936599802084e-07 -5.193177317477569e-06 -1.5763238779508608e-05" />
                                    <body name="servo_wrist_pitch_l" pos="-0.11970384512458687 0.01449999321109253 0.025545655743789128" euler="-3.141592653589793 -1.040834085586084e-15 -1.570796326794897">
                                        <geom name="servo_wrist_pitch_l_geom" type="mesh" mesh="servo_wrist_pitch_l" pos="0 0 0" euler="0 0 0" />
                                        <inertial mass="0.2574774645033229" pos="0.0166123637043133 0.03333463847036307 0.04754288849972692" fullinertia="4.435486308625164e-05 4.572278841339523e-05 7.311602559771996e-05 3.61306951284636e-07 7.027404484702672e-09 8.375458181079123e-09" />
                                        <body name="hand_l" pos="0.012000006788908025 0.03345384800005428 0.07154565551562758" euler="-7.216449660063417e-16 1.7774556554708131e-16 -1.5707963267948963">
                                            <joint name="servo_wrist_pitch_l_Revolute_wrist_pitch_l" type="hinge" axis="1.000000000000001 -1.0530111373632714e-16 2.0400348077486194e-15" pos="0.02475032412796322 0.0139999990314236 -0.02400032412796263" />
                                            <geom name="hand_l_geom" type="mesh" mesh="hand_l" pos="0 0 0" euler="0 0 0" />
                                            <geom name="hand_l_collision1" class="collision_geom" pos="0.027 0.047 -0.024" size="0.0015 0.04 0.01" />
                                            <geom name="hand_l_collision2" class="collision_geom" pos="0.036 0.0885 -0.024" size="0.0075 0.0015 0.01" />
                                            <geom name="hand_l_collision3" class="collision_geom" pos="0.045 0.085 -0.024" size="0.0015 0.005 0.01" />
                                            <inertial mass="0.017731524807570984" pos="0.007927371880112149 0.05055428177592201 -0.02400000000001021" fullinertia="1.1536574784611782e-05 1.2648677821680208e-05 2.303232142870454e-05 -4.71879004370487e-06 -7.086529111950366e-18 -6.95186072527565e-18" />
                                        </body>
                                    </body>
                                </body>
                            </body>
                        </body>
                    </body>
                </body>
            </body>
            <body name="servo_shoulder_roll_r" pos="-0.06710384800005419 0.10224999417966729 -0.00645434448437217" euler="-3.141592653589793 -3.871902798380109e-15 -1.5707963267948968">
                <geom name="servo_shoulder_roll_r_geom" type="mesh" mesh="servo_shoulder_roll_r" pos="0 0 0" euler="0 0 0" />
                <inertial mass="0.25164687718092266" pos="0.016295528106545578 0.03288647170679024 0.047544912714183846" fullinertia="4.143432390868366e-05 4.38226411165653e-05 6.936512928157383e-05 1.9005141956634722e-06 -1.0197049305254632e-10 -1.6884099913866388e-09" />
                <body name="shoulder_joint_r" pos="0.026000006788908365 -0.01254614532764429 -0.020204342316567994" euler="2.2204460492500937e-16 -1.5707963267948812 0">
                    <joint name="servo_shoulder_roll_r_Revolute_shoulder_roll_r" type="hinge" axis="1.026956297778166e-15 -1.0000000000000018 1.5238458040397422e-14" pos="0.06775032196015825 0.021249669199736195 9.685753664666641e-10" />
                    <geom name="shoulder_joint_r_geom" type="mesh" mesh="shoulder_joint_r" pos="0 0 0" euler="0 0 0" />
                    <inertial mass="0.013004386860980393" pos="0.0680837468028471 2.732322516576182e-05 -1.780874899310464e-14" fullinertia="5.276273904760669e-06 8.369185492904745e-06 1.2786255215626315e-05 1.1187878600832544e-07 -5.539037678144715e-18 -3.606979330923402e-18" />
                    <body name="servo_shoulder_pitch_r" pos="0.1022038458322508 -0.07329566218792871 0.02600000678890808" euler="-1.5707963267948963 -1.792308973233816e-14 1.5707963267948961">
                        <joint name="shoulder_joint_r_Revolute_shoulder_pitch_r" type="hinge" axis="1.9672445057763004e-16 -1.0000000000000024 -1.6896133434559994e-14" pos="0.026000005820332208 0.008703523872091837 0.04754533138766521" />
                        <geom name="servo_shoulder_pitch_r_geom" type="mesh" mesh="servo_shoulder_pitch_r" pos="0 0 0" euler="0 0 0" />
                        <inertial mass="0.2574774645033229" pos="0.016612363704313342 0.033334638470363165 0.04754288849972699" fullinertia="4.435486308624897e-05 4.572278841338839e-05 7.311602559771313e-05 3.613069512842962e-07 7.02740448427748e-09 8.375458181714025e-09" />
                        <body name="elbow_joint_r" pos="0.04600000678890694 0.030103848000053265 -0.008454344484372545" euler="-1.9345636204093226e-14 7.138904121942928e-15 3.141592653589793">
                            <geom name="elbow_joint_r_geom" type="mesh" mesh="elbow_joint_r" pos="0 0 0" euler="0 0 0" />
                            <inertial mass="0.0940156941457831" pos="0.030249999999995628 0.0025000000000000096 0.03600000000000013" fullinertia="3.813578891955738e-05 7.543913942454006e-05 3.767401128966689e-05 4.039212272294457e-21 9.56296168125774e-21 -8.73742279156162e-21" />
                            <body name="servo_elbow_pitch_r" pos="0.046000006788908296 0.03010384800005309 -0.03154565551562861" euler="-3.0239699633227626e-14 -3.019098597120969e-17 3.141592653589793">
                                <geom name="servo_elbow_pitch_r_geom" type="mesh" mesh="servo_elbow_pitch_r" pos="0 0 0" euler="0 0 0" />
                                <inertial mass="0.2574774645033229" pos="0.01661236370431332 0.03333463847036314 0.047542888499727" fullinertia="4.435486308625274e-05 4.572278841340221e-05 7.311602559772351e-05 3.6130695128463944e-07 7.0274044892918224e-09 8.375458181885596e-09" />
                                <body name="wrist_joint_r" pos="-0.014499993211091428 0.0087038480000543 0.06154565551562774" euler="-3.1415926535897927 6.123233995734068e-17 -1.5707963267948968">
                                    <joint name="servo_elbow_pitch_r_Revolute_elbow_pitch_r" type="hinge" axis="1.0000000000000036 -1.967244505776407e-16 -5.627369734614584e-15" pos="-3.2412796085138393e-07 0.04049999903142441 0.014000324127962272" />
                                    <geom name="wrist_joint_r_geom" type="mesh" mesh="wrist_joint_r" pos="0 0 0" euler="0 0 0" />
                                    <inertial mass="0.2138444469189373" pos="0.024312945201467564 0.03338795334782349 0.05311811492378441" fullinertia="0.00013956317461262627 0.00016881014969251428 0.00013951676965105812 -6.219365998040135e-07 5.19317731747766e-06 1.576323877950711e-05" />
                                    <body name="servo_wrist_pitch_r" pos="-0.008703848000054389 0.014499993211092316 0.128545655515628" euler="-3.141592653589793 -9.28424004342787e-15 -1.5707963267948968">
                                        <geom name="servo_wrist_pitch_r_geom" type="mesh" mesh="servo_wrist_pitch_r" pos="0 0 0" euler="0 0 0" />
                                        <inertial mass="0.2574774645033229" pos="0.01661236370431343 0.033334638470363186 0.047542888499726904" fullinertia="4.435486308624638e-05 4.572278841337451e-05 7.311602559769562e-05 3.6130695128429226e-07 7.027404481526693e-09 8.37545818225585e-09" />
                                        <body name="hand_r" pos="0.012000006788907882 0.03345384800005426 0.07154565551562742" euler="2.4980018054065613e-16 -5.417030312083779e-16 -1.5707963267948963">
                                            <joint name="servo_wrist_pitch_r_Revolute_wrist_pitch_r" type="hinge" axis="1.0000000000000004 -6.187792626253532e-16 3.90667048935397e-15" pos="0.024750324127959973 0.013999999031423611 -0.024000324127961558" />
                                            <geom name="hand_r_geom" type="mesh" mesh="hand_r" pos="0 0 0" euler="0 0 0" />
                                            <geom name="hand_r_collision1" class="collision_geom" pos="0.027 0.047 -0.024" size="0.0015 0.04 0.01" />
                                            <geom name="hand_r_collision2" class="collision_geom" pos="0.036 0.0885 -0.024" size="0.0075 0.0015 0.01" />
                                            <geom name="hand_r_collision3" class="collision_geom" pos="0.045 0.085 -0.024" size="0.0015 0.005 0.01" />
                                            <inertial mass="0.017731524807570984" pos="0.00792737188011213 0.05055428177592214 -0.024000000000010145" fullinertia="1.1536574784613063e-05 1.2648677821680628e-05 2.303232142870494e-05 -4.718790043704889e-06 -7.085163395125562e-18 -6.649286520524504e-18" />
                                        </body>
                                    </body>
                                </body>
                            </body>
                        </body>
                    </body>
                </body>
            </body>
            <body name="servo_hip_roll_l" pos="0.012249993211091858 0.014896151999945602 -0.10154565551562762" euler="-2.3894149132996693e-15 -5.273559366969496e-16 1.211661325477796e-29">
                <geom name="servo_hip_roll_l_geom" type="mesh" mesh="servo_hip_roll_l" pos="0 0 0" euler="0 0 0" />
                <inertial mass="0.25164687718092266" pos="0.01629552810654555 0.03288647170679009 0.047544912714183804" fullinertia="4.1434323908684525e-05 4.382264111655026e-05 6.936512928157373e-05 1.9005141956635252e-06 -1.0197049318925841e-10 -1.6884099899076522e-09" />
                <body name="hip_joint_l" pos="0.02600000678890776 0.0037038480000541087 0.04754565551562734" euler="1.3739009929735419e-15 3.3723024372987943e-15 -1.570796326794942">
                    <joint name="servo_hip_roll_l_Revolute_hip_roll_l" type="hinge" axis="-0.9999999999999998 -4.424585697826446e-14 1.0155139203261355e-15" pos="-0.005000000000000115 -3.2412796228871795e-07 -3.241279624718054e-07" />
                    <geom name="hip_joint_l_geom" type="mesh" mesh="hip_joint_l" pos="0 0 0" euler="0 0 0" />
                    <inertial mass="0.013004386860980387" pos="0.016222670102532834 0.00033374897065125374 -1.7783322461718984e-14" fullinertia="8.369185492904505e-06 5.2762739047604314e-06 1.2786255215626142e-05 -1.1187878600830893e-07 3.614087664711613e-18 -5.549018247775838e-18" />
                    <body name="servo_hip_pitch_l" pos="0.08954565551562724 0.03445384800005579 0.026000006788908375" euler="-3.141592653589793 -1.5707963267948672 0">
                        <joint name="hip_joint_l_Revolute_hip_pitch_l" type="hinge" axis="4.71844785465811e-16 -1.0000000000000018 1.6035340422079604e-14" pos="0.026000330916870994 0.00870417212801464 0.047545655515628685" />
                        <geom name="servo_hip_pitch_l_geom" type="mesh" mesh="servo_hip_pitch_l" pos="0 0 0" euler="0 0 0" />
                        <inertial mass="0.2574774645033229" pos="0.016612363704313477 0.03333463847036315 0.047542888499726974" fullinertia="4.4354863086253944e-05 4.572278841339007e-05 7.311602559771261e-05 3.613069512840749e-07 7.027404485425773e-09 8.37545818165592e-09" />
                        <body name="knee_joint_l" pos="-0.01449999321109165 0.025103848000055093 -0.00845434448437267" euler="1.230797310218865e-14 -2.498001805406498e-16 -1.5265566588598124e-16">
                            <geom name="knee_joint_l_geom" type="mesh" mesh="knee_joint_l" pos="0 0 0" euler="0 0 0" />
                            <inertial mass="0.0940156941457831" pos="0.03024999999999578 0.0025000000000000616 0.03600000000000019" fullinertia="3.81357889195584e-05 7.543913942454367e-05 3.7674011289666974e-05 3.5503586074200515e-20 3.514201509841717e-20 1.485896934364399e-20" />
                            <body name="servo_knee_pitch_l" pos="0.014499993211091793 -0.02510384800005456 -0.0315456555156271" euler="-3.602687309886994e-15 8.60422844084485e-16 6.938893903907782e-17">
                                <geom name="servo_knee_pitch_l_geom" type="mesh" mesh="servo_knee_pitch_l" pos="0 0 0" euler="0 0 0" />
                                <inertial mass="0.2574774645033229" pos="0.016612363704313463 0.03333463847036305 0.04754288849972685" fullinertia="4.4354863086255544e-05 4.5722788413390895e-05 7.311602559771288e-05 3.6130695128469333e-07 7.027404485445636e-09 8.375458180035064e-09" />
                                <body name="ankle_joint_l" pos="-0.014499993211091602 0.008703848000054375 0.061545655515627455" euler="3.1415926535897896 3.053113317719169e-16 -1.5707963267948968">
                                    <joint name="servo_knee_pitch_l_Revolute_knee_pitch_l" type="hinge" axis="0.9999999999999987 -9.714451465482809e-17 2.1181668611083982e-14" pos="3.241279591759234e-07 0.040500324127962395 0.013999999999998701" />
                                    <geom name="ankle_joint_l_geom" type="mesh" mesh="ankle_joint_l" pos="0 0 0" euler="0 0 0" />
                                    <inertial mass="0.2138444469189373" pos="0.02431294520146735 0.03338795334782341 0.0531181149237841" fullinertia="0.0001395631746126177 0.00016881014969251552 0.00013951676965105161 -6.219365998039449e-07 5.1931773174781224e-06 1.5763238779507913e-05" />
                                    <body name="servo_ankle_pitch_l" pos="-0.008703848000054039 0.01449999321109173 0.128545655515628" euler="-3.141592653589793 -9.415384058194912e-15 -1.570796326794896">
                                        <geom name="servo_ankle_pitch_l_geom" type="mesh" mesh="servo_ankle_pitch_l" pos="0 0 0" euler="0 0 0" />
                                        <inertial mass="0.2574774645033229" pos="0.01661236370431339 0.03333463847036322 0.04754288849972695" fullinertia="4.435486308624839e-05 4.572278841339283e-05 7.311602559771088e-05 3.6130695128548393e-07 7.027404485144172e-09 8.375458180230965e-09" />
                                        <body name="foot_l" pos="0.13462305689347764 0.0510649908305853 -0.0411129356310456" euler="1.5707963267948952 -7.025106852471869e-15 1.1657341758563806e-15">
                                            <joint name="servo_ankle_pitch_l_Revolute_ankle_pitch_l" type="hinge" axis="-6.9111383282915734e-15 -2.8742589122153243e-14 -1.0000000000000018" pos="-0.10862272597660667 0.08865859114667457 0.04236081870257435" />
                                            <geom name="foot_l_geom" type="mesh" mesh="foot_l" pos="0 0 0" euler="0 0 0" />
                                            <geom name="foot_l_collision1" class="collision_geom" pos="-0.0959 0.0315 0.0165" size="0.036 0.002 0.025" />
                                            <geom name="foot_l_collision2" class="collision_geom" pos="-0.062 0.026 0.0165" size="0.002 0.004 0.025" />
                                            <inertial mass="0.03234169397495974" pos="-0.10074037993742484 0.044552703523581566 0.016745341142227112" fullinertia="2.372598379584238e-05 2.1909544465465758e-05 2.2944028519021376e-05 3.718963348874319e-06 3.421237080125402e-08 -1.9142840560623252e-07" />
                                        </body>
                                    </body>
                                </body>
                            </body>
                        </body>
                    </body>
                </body>
            </body>
            <body name="servo_hip_roll_r" pos="-0.01224999321109177 0.014896151999945744 -0.006454344484372419" euler="3.141592653589792 -4.4165379949446923e-16 3.141592653589793">
                <geom name="servo_hip_roll_r_geom" type="mesh" mesh="servo_hip_roll_r" pos="0 0 0" euler="0 0 0" />
                <inertial mass="0.25164687718092266" pos="0.016295528106545523 0.032886471706789926 0.04754491271418353" fullinertia="4.143432390868791e-05 4.382264111655233e-05 6.936512928157337e-05 1.9005141956630373e-06 -1.0197049237844719e-10 -1.688409991676879e-09" />
                <body name="hip_joint_r" pos="0.026000006788908316 0.0037038480000542153 0.04754565551562753" euler="-5.134781488890332e-16 2.347781549876113e-15 -1.5707963267948994">
                    <joint name="servo_hip_roll_r_Revolute_hip_roll_r" type="hinge" axis="-0.9999999999999996 -1.082467449009515e-15 -7.240803763620361e-16" pos="-0.005000000000000085 3.241279624055515e-07 3.2412796238652686e-07" />
                    <geom name="hip_joint_r_geom" type="mesh" mesh="hip_joint_r" pos="0 0 0" euler="0 0 0" />
                    <inertial mass="0.013004386860980387" pos="0.016222670102532845 0.0003337489706512373 -1.77828756997368e-14" fullinertia="8.369185492904517e-06 5.276273904760438e-06 1.2786255215626067e-05 -1.1187878600835042e-07 3.6138960092588606e-18 -5.5518007908176e-18" />
                    <body name="servo_hip_pitch_r" pos="-0.00554565551562753 0.0344538480000539 -0.026000006788908347" euler="-3.141592653589793 1.5707963267948915 0">
                        <joint name="hip_joint_r_Revolute_hip_pitch_r" type="hinge" axis="-2.081668171173353e-16 -1.0000000000000036 2.3031013741508997e-15" pos="0.026000330916870953 0.008703523872091591 0.04754565551562743" />
                        <geom name="servo_hip_pitch_r_geom" type="mesh" mesh="servo_hip_pitch_r" pos="0 0 0" euler="0 0 0" />
                        <inertial mass="0.2574774645033229" pos="0.016612363704313543 0.03333463847036322 0.04754288849972696" fullinertia="4.4354863086264434e-05 4.572278841339717e-05 7.311602559771229e-05 3.613069512851621e-07 7.027404485383338e-09 8.37545818072574e-09" />
                        <body name="knee_joint_r" pos="-0.014499993211091567 0.025103848000054253 0.031545655515627435" euler="-7.243593833732837e-15 1.2351231148954813e-15 1.249000902703176e-16">
                            <geom name="knee_joint_r_geom" type="mesh" mesh="knee_joint_r" pos="0 0 0" euler="0 0 0" />
                            <inertial mass="0.0940156941457831" pos="0.030249999999995718 0.002500000000000003 0.036000000000000074" fullinertia="3.8135788919557815e-05 7.543913942454017e-05 3.7674011289665646e-05 3.9656752527054275e-20 4.209527952360708e-19 -3.653608692617344e-20" />
                            <body name="servo_knee_pitch_r" pos="0.01449999321109186 -0.025103848000054666 0.008454344484372918" euler="-5.8009153036664374e-15 -1.0963452368173419e-15 4.163336342342771e-17">
                                <geom name="servo_knee_pitch_r_geom" type="mesh" mesh="servo_knee_pitch_r" pos="0 0 0" euler="0 0 0" />
                                <inertial mass="0.2574774645033229" pos="0.0166123637043134 0.033334638470363144 0.047542888499727036" fullinertia="4.435486308625019e-05 4.572278841338478e-05 7.311602559771272e-05 3.6130695128449497e-07 7.027404485723497e-09 8.375458183912104e-09" />
                                <body name="ankle_joint_r" pos="-0.014499993211091713 0.008703848000054198 0.03354565551562718" euler="3.247402347028571e-15 1.304512053934559e-15 -1.5707963267948968">
                                    <joint name="servo_knee_pitch_r_Revolute_knee_pitch_r" type="hinge" axis="-0.999999999999999 8.326672684689947e-16 7.494005416219832e-15" pos="3.2412796280709455e-07 0.04050032412796231 0.013999999999999877" />
                                    <geom name="ankle_joint_r_geom" type="mesh" mesh="ankle_joint_r" pos="0 0 0" euler="0 0 0" />
                                    <inertial mass="0.2138444469189369" pos="-0.02431294520146747 0.033387953347823504 0.05311811492352507" fullinertia="0.00013956317464031544 0.00016881014972867572 0.0001395167696425888 6.219365998020569e-07 -5.19317731754364e-06 1.576323877990438e-05" />
                                    <body name="servo_ankle_pitch_r" pos="0.00870384800005548 0.014499993211091633 0.033454344484373504" euler="1.5265566588595454e-16 -3.168125484176445e-14 1.570796326794896">
                                        <geom name="servo_ankle_pitch_r_geom" type="mesh" mesh="servo_ankle_pitch_r" pos="0 0 0" euler="0 0 0" />
                                        <inertial mass="0.2574774645033229" pos="0.016612363704313432 0.0333346384703631 0.047542888499726904" fullinertia="4.4354863086254134e-05 4.5722788413389554e-05 7.31160255977125e-05 3.6130695128479477e-07 7.027404486096344e-09 8.375458182176075e-09" />
                                        <body name="foot_r" pos="0.13462305689347837 0.05106499083058376 0.1362042466623009" euler="-1.5707963267948952 2.1558950229753837e-14 2.3592239273279143e-16">
                                            <joint name="servo_ankle_pitch_r_Revolute_ankle_pitch_r" type="hinge" axis="2.1482815526496826e-14 3.7545045805745404e-14 -1.0000000000000029" pos="-0.10862272597660758 0.08865859114667445 -0.0423614669584958" />
                                            <geom name="foot_r_geom" type="mesh" mesh="foot_r" pos="0 0 0" euler="0 0 0" />
                                            <geom name="foot_r_collision1" class="collision_geom" pos="-0.0965 0.0315 -0.017" size="0.036 0.002 0.025" />
                                            <geom name="foot_r_collision2" class="collision_geom" pos="-0.062 0.026 -0.017" size="0.002 0.004 0.025" />
                                            <inertial mass="0.03234169397496026" pos="-0.10074037993738615 0.04455270352358195 -0.0167453411422271" fullinertia="2.3725983791337153e-05 2.190954446694808e-05 2.294402851599545e-05 3.718963348818869e-06 -3.4212370799608215e-08 1.9142840560624363e-07" />
                                        </body>
                                    </body>
                                </body>
                            </body>
                        </body>
                    </body>
                </body>
            </body>
        </body>
    </worldbody>

    <actuator>
        <!-- Right Arm -->
        <position name="shoulder_roll_r" joint="servo_shoulder_roll_r_Revolute_shoulder_roll_r"/>
        <position name="shoulder_pitch_r"          joint="shoulder_joint_r_Revolute_shoulder_pitch_r" />
        <position name="elbow_pitch_r"          joint="servo_elbow_pitch_r_Revolute_elbow_pitch_r" />
        <position name="wrist_pitch_r"          joint="servo_wrist_pitch_r_Revolute_wrist_pitch_r" />

        <!-- Left Arm -->
        <position name="shoulder_roll_l" joint="servo_shoulder_roll_l_Revolute_shoulder_roll_l"/>
        <position name="shoulder_pitch_l"          joint="shoulder_joint_l_Revolute_shoulder_pitch_l" />
        <position name="elbow_pitch_l"          joint="servo_elbow_pitch_l_Revolute_elbow_pitch_l" />
        <position name="wrist_pitch_l"          joint="servo_wrist_pitch_l_Revolute_wrist_pitch_l" />

        <!-- Right Leg -->
        <position name="hip_roll_r"   joint="servo_hip_roll_r_Revolute_hip_roll_r" />
        <position name="hip_pitch_r"  joint="hip_joint_r_Revolute_hip_pitch_r" />
        <position name="knee_pitch_r" joint="servo_knee_pitch_r_Revolute_knee_pitch_r" />
        <position name="ankle_pitch_r" joint="servo_ankle_pitch_r_Revolute_ankle_pitch_r" />

        <!-- Left Leg -->
        <position name="hip_roll_l"   joint="servo_hip_roll_l_Revolute_hip_roll_l" />
        <position name="hip_pitch_l"  joint="hip_joint_l_Revolute_hip_pitch_l" />
        <position name="knee_pitch_l" joint="servo_knee_pitch_l_Revolute_knee_pitch_l" />
        <position name="ankle_pitch_l" joint="servo_ankle_pitch_l_Revolute_ankle_pitch_l" />
    </actuator>

</mujoco>